<?xml version="1.0" ?>
<!-- =================================================================================== -->
<!-- |    This document was autogenerated by xacro from robot.urdf.xacro               | -->
<!-- |    EDITING THIS FILE BY HAND IS NOT RECOMMENDED                                 | -->
<!-- =================================================================================== -->
<robot name="amigo" xmlns:controller="http://playerstage.sourceforge.net/gazebo/xmlschema/#controller" xmlns:interface="http://playerstage.sourceforge.net/gazebo/xmlschema/#interface" xmlns:sensor="http://playerstage.sourceforge.net/gazebo/xmlschema/#sensor" xmlns:xacro="http://ros.org/wiki/xacro">
  <!--get plugins -->
  <gazebo>
    <controller:gazebo_ros_time name="gazebo_ros_time" plugin="libgazebo_ros_time.so">
      <alwaysOn>true</alwaysOn>
      <updateRate>1000.0</updateRate>
      <interface:audio name="dummy_gazebo_ros_time_iface_should_not_be_here"/>
    </controller:gazebo_ros_time>
    <controller:gazebo_ros_controller_manager name="gazebo_ros_controller_manager" plugin="libgazebo_ros_controller_manager.so">
      <alwaysOn>true</alwaysOn>
      <updateRate>1000.0</updateRate>
      <interface:audio name="gazebo_ros_controller_manager_dummy_iface"/>
    </controller:gazebo_ros_controller_manager>
    <controller:gazebo_ros_imu name="imu_controller" plugin="libgazebo_ros_imu.so">
      <alwaysOn>true</alwaysOn>
      <updateRate>1000.0</updateRate>
      <bodyName>base_link</bodyName>
      <topicName>body_pose_ground_truth</topicName>
      <xyzOffsets>0.0 0.0 0</xyzOffsets>
      <rpyOffsets>0 0 0</rpyOffsets>
      <interface:position name="imu_position_iface"/>
    </controller:gazebo_ros_imu>
    <controller:gazebo_ros_p3d name="base_controller" plugin="libgazebo_ros_p3d.so">
      <alwaysOn>true</alwaysOn>
      <updateRate>100.0</updateRate>
      <bodyName>base_link</bodyName>
      <topicName>base_pose_ground_truth</topicName>
      <gaussianNoise>0.01</gaussianNoise>
      <frameName>map</frameName>
      <xyzOffsets>25.7 25.7 0</xyzOffsets>
      <!-- initialize odometry for fake localization-->
      <rpyOffsets>0 0 0</rpyOffsets>
      <interface:position name="p3d_base_position"/>
    </controller:gazebo_ros_p3d>
  </gazebo>
  <gazebo reference="base_laser">
    <sensor:ray name="base_ray_sensor">
      <origin>0.0 0.0 0.0</origin>
      <rayCount>683</rayCount>
      <rangeCount>683</rangeCount>
      <laserCount>1</laserCount>
      <displayRays>false</displayRays>
      <minAngle>-135</minAngle>
      <maxAngle> 135</maxAngle>
      <minRange>0.05</minRange>
      <maxRange>10.0</maxRange>
      <resRange>0.01</resRange>
      <updateRate>100.0</updateRate>
      <controller:gazebo_ros_laser name="base_ros_ray_sensor_controller" plugin="libgazebo_ros_laser.so">
        <gaussianNoise>0.005</gaussianNoise>
        <alwaysOn>true</alwaysOn>
        <updateRate>15.0</updateRate>
        <topicName>base_scan</topicName>
        <frameName>/base_laser</frameName>
        <interface:laser name="base_ros_ray_sensor_iface"/>
      </controller:gazebo_ros_laser>
    </sensor:ray>
  </gazebo>
  <gazebo reference="top_laser">
    <sensor:ray name="top_ray_sensor">
      <origin>0.0 0.0 0.0</origin>
      <rayCount>683</rayCount>
      <rangeCount>683</rangeCount>
      <laserCount>1</laserCount>
      <displayRays>false</displayRays>
      <minAngle>-135</minAngle>
      <maxAngle> 135</maxAngle>
      <minRange>0.05</minRange>
      <maxRange>10.0</maxRange>
      <resRange>0.01</resRange>
      <updateRate>100.0</updateRate>
      <controller:gazebo_ros_laser name="top_ros_ray_sensor_controller" plugin="libgazebo_ros_laser.so">
        <gaussianNoise>0.005</gaussianNoise>
        <alwaysOn>true</alwaysOn>
        <updateRate>15.0</updateRate>
        <topicName>top_scan</topicName>
        <frameName>/top_laser</frameName>
        <interface:laser name="top_ros_ray_sensor_iface"/>
      </controller:gazebo_ros_laser>
    </sensor:ray>
  </gazebo>
  <gazebo reference="camera_center">
    <sensor:camera name="camera_center_sensor">
      <controller:gazebo_ros_camera name="controller_center-name" plugin="libgazebo_ros_camera.so">
        <alwaysOn>true</alwaysOn>
        <updateRate>15.0</updateRate>
        <imageTopicName>/center/image_raw</imageTopicName>
        <cameraInfoTopicName>/center/camera_info</cameraInfoTopicName>
        <frameName>/camera_tf</frameName>
      </controller:gazebo_ros_camera>
    </sensor:camera>
  </gazebo>
  <!--get link & joint definitions -->
  <!--========BUILD BODY======-->
  <link name="base">
    <inertial>
      <origin rpy="0 0 0" xyz="0.0 0.0 0.0"/>
      <mass value="20"/>
      <inertia ixx="2.63" ixy="0" ixz="0" iyy="2.63" iyz="0" izz="2.4"/>
    </inertial>
    <visual>
      <origin rpy="0 0 0" xyz="0.0 0.0 0.0"/>
      <geometry>
        <box size="0.2 0.2 0.655"/>
      </geometry>
      <material name="Red">
        <color rgba="0.5 0.5 0.5  1.0"/>
      </material>
    </visual>
    <collision>
      <origin rpy="0 0 0" xyz="0.0 0.0 0.0"/>
      <geometry>
        <box size="0.2 0.2 0.655"/>
      </geometry>
    </collision>
  </link>
  <gazebo reference="base">
    <material>Gazebo/Red</material>
    <turnGravityOff>false</turnGravityOff>
  </gazebo>
  <link name="torso_slider">
    <inertial>
      <origin rpy="0 0 0" xyz="0.0 0.0 0.0"/>
      <mass value="0.1"/>
      <inertia ixx="0.1" ixy="0" ixz="0" iyy="0.1" iyz="0" izz="0.1"/>
    </inertial>
    <visual>
      <origin rpy="0 0 0" xyz="0.0 0.0 0.0"/>
      <geometry>
        <box size="0.2 0.2 0.655"/>
      </geometry>
      <material name="Red">
        <color rgba="0.5 0.5 0.5  1.0"/>
      </material>
    </visual>
    <collision>
      <origin rpy="0 0 0" xyz="0.0 0.0 0.0"/>
      <geometry>
        <box size="0.2 0.2 0.655"/>
      </geometry>
    </collision>
  </link>
  <gazebo reference="torso_slider">
    <material>Gazebo/Red</material>
    <turnGravityOff>false</turnGravityOff>
  </gazebo>
  <link name="base_link">
    <inertial>
      <origin rpy="0 0 0" xyz="0.0 0.0 0.0"/>
      <mass value="20"/>
      <inertia ixx="0.001" ixy="0" ixz="0" iyy="0.001" iyz="0" izz="0.001"/>
    </inertial>
    <visual>
      <origin rpy="0 0 0" xyz="0.0 0.0 0.0"/>
      <geometry>
        <cylinder length="0.05" radius="0.35"/>
      </geometry>
      <material name="Red">
        <color rgba="0.5 0.5 0.5  1.0"/>
      </material>
    </visual>
    <collision>
      <origin rpy="0 0 0" xyz="0.0 0.0 0.0"/>
      <geometry>
        <cylinder length="0.05" radius="0.35"/>
      </geometry>
    </collision>
  </link>
  <gazebo reference="base_link">
    <material>Gazebo/Red</material>
    <turnGravityOff>false</turnGravityOff>
  </gazebo>
  <link name="torso">
    <inertial>
      <origin rpy="0 0 0" xyz="0.0475 0.0 0.0"/>
      <mass value="16"/>
      <inertia ixx="0.01" ixy="0" ixz="0" iyy="0.01" iyz="0" izz="0.01"/>
    </inertial>
    <visual>
      <origin rpy="1.5708 1.5708 1.5708" xyz="0.0475 0.0 0.0"/>
      <geometry>
        <box size="0.2  0.387 0.097   "/>
      </geometry>
      <material name="Green">
        <color rgba="0.4 0.4 0.4 1.0"/>
      </material>
    </visual>
    <collision>
      <origin rpy="1.5708 1.5708 1.5708" xyz="0.0475 0.0 0.0"/>
      <geometry>
        <box size="0.2  0.387 0.097   "/>
      </geometry>
    </collision>
  </link>
  <gazebo reference="torso">
    <material>Gazebo/Green</material>
    <turnGravityOff>false</turnGravityOff>
  </gazebo>
  <joint name="spindle_joint" type="prismatic">
    <parent link="base"/>
    <child link="torso"/>
    <axis xyz="1 0 0"/>
    <origin rpy="3.14159265 -1.5708 0" xyz="0.0 0.0 0.3325"/>
    <dynamics damping="3" friction="0.0"/>
    <!--*-->
    <limit effort="30" lower="0.0" upper="0.41" velocity="1.0"/>
    <!--*-->
  </joint>
  <joint name="base_link_joint" type="fixed">
    <parent link="base_link"/>
    <child link="base"/>
    <axis xyz="1 0 0"/>
    <origin rpy="0 0 0" xyz="0.0 0.0 0.3475"/>
  </joint>
  <joint name="torso_slider_joint" type="fixed">
    <parent link="torso"/>
    <child link="torso_slider"/>
    <axis xyz="1 0 0"/>
    <origin rpy="0 1.57 0" xyz="  -0.33 0.0 0.0"/>
  </joint>
  <!--========BUILD HEAD======-->
  <link name="head_mount">
    <inertial>
      <origin rpy="0 0 0" xyz="0.0 0.0 0.0"/>
      <mass value="0.05"/>
      <inertia ixx="0.0001" ixy="0" ixz="0" iyy="0.0001" iyz="0" izz="0.0001"/>
    </inertial>
    <visual>
      <origin rpy="0 0 0" xyz="0.0 0.0 0.0"/>
      <geometry>
        <box size="0.01 0.01  0.01 "/>
      </geometry>
      <material name="Blue">
        <color rgba="0.25 0.25 0.25 1.0"/>
      </material>
    </visual>
    <collision>
      <origin rpy="0 0 0" xyz="0.0 0.0 0.0"/>
      <geometry>
        <box size="0.01 0.01  0.01 "/>
      </geometry>
    </collision>
  </link>
  <gazebo reference="head_mount">
    <material>Gazebo/Blue</material>
    <turnGravityOff>false</turnGravityOff>
  </gazebo>
  <link name="neck_pan">
    <inertial>
      <origin rpy="0 0 0" xyz="0.0 0.0 0.0335"/>
      <mass value="0.05"/>
      <inertia ixx="0.0001" ixy="0" ixz="0" iyy="0.0001" iyz="0" izz="0.0001"/>
    </inertial>
    <visual>
      <origin rpy="0 0 0" xyz="0.0 0.0 0.0335"/>
      <geometry>
        <cylinder length="0.08" radius="0.015"/>
      </geometry>
      <material name="Blue">
        <color rgba="0.25 0.25 0.25 1.0"/>
      </material>
    </visual>
    <collision>
      <origin rpy="0 0 0" xyz="0.0 0.0 0.0335"/>
      <geometry>
        <cylinder length="0.08" radius="0.015"/>
      </geometry>
    </collision>
  </link>
  <gazebo reference="neck_pan">
    <material>Gazebo/Blue</material>
    <turnGravityOff>false</turnGravityOff>
  </gazebo>
  <link name="head">
    <inertial>
      <origin rpy="0 0 0" xyz="0.0 -0.0 0.0"/>
      <mass value="0.7"/>
      <inertia ixx="0.001" ixy="0" ixz="0" iyy="0.001" iyz="0" izz="0.001"/>
    </inertial>
    <visual>
      <origin rpy="0 0 0" xyz="0.0 -0.0 0.0"/>
      <geometry>
        <box size="0.036 0.24  0.036 "/>
      </geometry>
      <material name="Yellow">
        <color rgba="1 0.64 0 1.0"/>
      </material>
    </visual>
    <collision>
      <origin rpy="0 0 0" xyz="0.0 -0.0 0.0"/>
      <geometry>
        <box size="0.036 0.24  0.036 "/>
      </geometry>
    </collision>
  </link>
  <gazebo reference="head">
    <material>Gazebo/Yellow</material>
    <turnGravityOff>false</turnGravityOff>
  </gazebo>
  <link name="neck_tilt">
    <inertial>
      <origin rpy="0 0 0" xyz="0.0 -0.0 0.0285"/>
      <mass value="0.05"/>
      <inertia ixx="0.001" ixy="0" ixz="0" iyy="0.001" iyz="0" izz="0.001"/>
    </inertial>
    <visual>
      <origin rpy="0 0 0" xyz="0.0 -0.0 0.0285"/>
      <geometry>
        <cylinder length="0.057" radius="0.015"/>
      </geometry>
      <material name="Blue">
        <color rgba="0.25 0.25 0.25 1.0"/>
      </material>
    </visual>
    <collision>
      <origin rpy="0 0 0" xyz="0.0 -0.0 0.0285"/>
      <geometry>
        <cylinder length="0.057" radius="0.015"/>
      </geometry>
    </collision>
  </link>
  <gazebo reference="neck_tilt">
    <material>Gazebo/Blue</material>
    <turnGravityOff>false</turnGravityOff>
  </gazebo>
  <link name="camera_center">
    <inertial>
      <origin rpy="0 0 0" xyz="0.0 0.0 0.0"/>
      <mass value="0.01"/>
      <inertia ixx="0.00001" ixy="0" ixz="0" iyy="0.00001" iyz="0" izz="0.00001"/>
    </inertial>
    <visual>
      <origin rpy="0 0 0" xyz="0.0 0.0 0.0"/>
      <geometry>
        <box size="0.01 0.01 0.01"/>
      </geometry>
      <material name="Blue">
        <color rgba="0.25 0.25 0.25 1.0"/>
      </material>
    </visual>
    <collision>
      <origin rpy="0 0 0" xyz="0.0 0.0 0.0"/>
      <geometry>
        <box size="0.01 0.01 0.01"/>
      </geometry>
    </collision>
  </link>
  <gazebo reference="camera_center">
    <material>Gazebo/Blue</material>
    <turnGravityOff>false</turnGravityOff>
  </gazebo>
  <link name="camera_tf">
    <inertial>
      <origin rpy="0 0 0" xyz="0.0 0.0 0.0"/>
      <mass value="0.01"/>
      <inertia ixx="0.00001" ixy="0" ixz="0" iyy="0.00001" iyz="0" izz="0.00001"/>
    </inertial>
    <visual>
      <origin rpy="0 0 0" xyz="0.0 0.0 0.0"/>
      <geometry>
        <box size="0.001 0.001 0.001"/>
      </geometry>
      <material name="Blue">
        <color rgba="0.25 0.25 0.25 1.0"/>
      </material>
    </visual>
    <collision>
      <origin rpy="0 0 0" xyz="0.0 0.0 0.0"/>
      <geometry>
        <box size="0.001 0.001 0.001"/>
      </geometry>
    </collision>
  </link>
  <gazebo reference="camera_tf">
    <material>Gazebo/Blue</material>
    <turnGravityOff>false</turnGravityOff>
  </gazebo>
  <link name="openni_camera">
    <inertial>
      <origin rpy="0 0 0" xyz="0.0 0.0 0.0"/>
      <mass value="0.01"/>
      <inertia ixx="0.00001" ixy="0" ixz="0" iyy="0.00001" iyz="0" izz="0.00001"/>
    </inertial>
    <visual>
      <origin rpy="0 0 0" xyz="0.0 0.0 0.0"/>
      <geometry>
        <box size="0.001 0.001 0.001"/>
      </geometry>
      <material name="Blue">
        <color rgba="0.25 0.25 0.25 1.0"/>
      </material>
    </visual>
    <collision>
      <origin rpy="0 0 0" xyz="0.0 0.0 0.0"/>
      <geometry>
        <box size="0.001 0.001 0.001"/>
      </geometry>
    </collision>
  </link>
  <gazebo reference="openni_camera">
    <material>Gazebo/Blue</material>
    <turnGravityOff>false</turnGravityOff>
  </gazebo>
  <joint name="head_mount_joint" type="fixed">
    <parent link="torso"/>
    <child link="head_mount"/>
    <axis xyz="0  0 1"/>
    <origin rpy="  0.0 0.0 0.0" xyz="0.097 0.0 0.046"/>
  </joint>
  <joint name="neck_pan_joint" type="revolute">
    <parent link="head_mount"/>
    <child link="neck_pan"/>
    <origin rpy="3.14 -1.5708 0.0" xyz="0.0 0.0 0.0"/>
    <axis xyz="0 0 1"/>
    <dynamics damping="0.1" friction="0"/>
    <limit effort="13.4" lower="-1.5708" upper="1.5708" velocity="1.0"/>
  </joint>
  <joint name="neck_tilt_joint" type="revolute">
    <parent link="neck_pan"/>
    <child link="neck_tilt"/>
    <origin rpy="0.0 0.0 0.0" xyz="0.0 0.0 0.0445"/>
    <axis xyz="0 1 0"/>
    <dynamics damping="0.1" friction="0.0"/>
    <limit effort="13.4" lower="-2.0" upper="2.0" velocity="1.0"/>
  </joint>
  <joint name="camera_center_joint" type="fixed">
    <parent link="head"/>
    <child link="camera_center"/>
    <axis xyz="0  0 1"/>
    <origin rpy=" 0.0 0.0 0.0" xyz="0.0 0.0  0.0"/>
  </joint>
  <joint name="camera_tf_joint" type="fixed">
    <parent link="head"/>
    <child link="camera_tf"/>
    <axis xyz="0  0 1"/>
    <origin rpy="-1.5708 0.0 -1.5708" xyz="0.0 0.0  0.0"/>
  </joint>
  <joint name="head_joint" type="fixed">
    <parent link="neck_tilt"/>
    <child link="head"/>
    <axis xyz="0  0 1"/>
    <origin rpy="  0.0 0.0 0.0" xyz="0.0 0.0 0.061"/>
  </joint>
  <joint name="kinect_joint" type="fixed">
    <parent link="head"/>
    <!--checked-->
    <child link="openni_camera"/>
    <axis xyz="0  0 1"/>
    <origin rpy="  0.0 0.0 0.0" xyz="0.026 0.018 0.0"/>
  </joint>
  <!--========BUILD LASER======-->
  <link name="base_laser">
    <inertial>
      <origin rpy="0 0 0" xyz="0.0 0.0 0.0"/>
      <mass value="0.5"/>
      <inertia ixx="0.0001" ixy="0" ixz="0" iyy="0.0001" iyz="0" izz="0.0001"/>
    </inertial>
    <visual>
      <origin rpy="0 0 0" xyz="0.0 0.0 0.0"/>
      <geometry>
        <box size="0.05 0.05 0.05"/>
      </geometry>
      <material name="Black">
        <color rgba="0.15 0.15 0.15 1.0"/>
      </material>
    </visual>
    <collision>
      <origin rpy="0 0 0" xyz="0.0 0.0 0.0"/>
      <geometry>
        <box size="0.05 0.05 0.05"/>
      </geometry>
    </collision>
  </link>
  <gazebo reference="base_laser">
    <material>Gazebo/Black</material>
    <turnGravityOff>false</turnGravityOff>
  </gazebo>
  <link name="top_laser">
    <inertial>
      <origin rpy="0 0 0" xyz="0.0 0.0 0.0"/>
      <mass value="0.005"/>
      <inertia ixx="0.0001" ixy="0" ixz="0" iyy="0.0001" iyz="0" izz="0.0001"/>
    </inertial>
    <visual>
      <origin rpy="0 0 0" xyz="0.0 0.0 0.0"/>
      <geometry>
        <box size="0.005 0.005 0.005"/>
      </geometry>
      <material name="Black">
        <color rgba="0.15 0.15 0.15 1.0"/>
      </material>
    </visual>
    <collision>
      <origin rpy="0 0 0" xyz="0.0 0.0 0.0"/>
      <geometry>
        <box size="0.005 0.005 0.005"/>
      </geometry>
    </collision>
  </link>
  <gazebo reference="top_laser">
    <material>Gazebo/Black</material>
    <turnGravityOff>false</turnGravityOff>
  </gazebo>
  <joint name="base_laser_joint" type="revolute">
    <parent link="base"/>
    <child link="base_laser"/>
    <origin rpy="0 0 0" xyz="0.31 0.0 -0.2"/>
    <axis xyz="0 1 0"/>
    <dynamics damping="0.1" friction="0"/>
    <limit effort="13.4" lower="-0.7809" upper="1.5708" velocity="1.0"/>
  </joint>
  <joint name="top_laser_joint" type="revolute">
    <parent link="head"/>
    <child link="top_laser"/>
    <origin rpy=" 0 0 0" xyz="0.05 0.0 0.0"/>
    <axis xyz="0 1 0"/>
    <dynamics damping="0.1" friction="0"/>
    <limit effort="13.4" lower="-1.5708" upper="1.5708" velocity="1.0"/>
  </joint>
  <!--========BUILD BASE KINECT======-->
  <!--<include filename="$(find amigo_robot_model)/base_kinect/base_kinect.urdf.xacro" />-->
  <!--========BUILD WHEELS======-->
  <joint name="omni_sphere1_joint_left_front" type="continuous">
    <parent link="wheel_left_front"/>
    <child link="omni_sphere1_left_front"/>
    <axis xyz="0 1 0"/>
    <origin rpy="0.0 0 0" xyz="0.0 0.03 0.0"/>
    <dynamics damping="0.01" friction="0.0"/>
    <limit effort="0.5" velocity="0.05"/>
  </joint>
  <link name="omni_sphere1_left_front">
    <inertial>
      <origin rpy="0 0 0" xyz="0.0 0.0 0.0"/>
      <mass value="0.05"/>
      <inertia ixx="0.000018" ixy="0" ixz="0" iyy="0.000018" iyz="0" izz="0.000018"/>
    </inertial>
    <visual>
      <origin rpy="0 0 0" xyz="0.0 0.0 0.0"/>
      <geometry>
        <sphere radius="0.03"/>
      </geometry>
      <material name="Blue">
        <color rgba="0.33 0.33 0.33 1.0"/>
      </material>
    </visual>
    <collision>
      <origin rpy="0 0 0" xyz="0.0 0.0 0.0"/>
      <geometry>
        <sphere radius="0.03"/>
      </geometry>
    </collision>
  </link>
  <gazebo reference="omni_sphere1_left_front">
    <material>Gazebo/Blue</material>
    <turnGravityOff>false</turnGravityOff>
  </gazebo>
  <joint name="omni_sphere1_joint_right_front" type="continuous">
    <parent link="wheel_right_front"/>
    <child link="omni_sphere1_right_front"/>
    <axis xyz="0 1 0"/>
    <origin rpy="0.0 0 0" xyz="0.0 0.03 0.0"/>
    <dynamics damping="0.01" friction="0.0"/>
    <limit effort="0.5" velocity="0.05"/>
  </joint>
  <link name="omni_sphere1_right_front">
    <inertial>
      <origin rpy="0 0 0" xyz="0.0 0.0 0.0"/>
      <mass value="0.05"/>
      <inertia ixx="0.000018" ixy="0" ixz="0" iyy="0.000018" iyz="0" izz="0.000018"/>
    </inertial>
    <visual>
      <origin rpy="0 0 0" xyz="0.0 0.0 0.0"/>
      <geometry>
        <sphere radius="0.03"/>
      </geometry>
      <material name="Blue">
        <color rgba="0.33 0.33 0.33 1.0"/>
      </material>
    </visual>
    <collision>
      <origin rpy="0 0 0" xyz="0.0 0.0 0.0"/>
      <geometry>
        <sphere radius="0.03"/>
      </geometry>
    </collision>
  </link>
  <gazebo reference="omni_sphere1_right_front">
    <material>Gazebo/Blue</material>
    <turnGravityOff>false</turnGravityOff>
  </gazebo>
  <joint name="omni_sphere1_joint_left_rear" type="continuous">
    <parent link="wheel_left_rear"/>
    <child link="omni_sphere1_left_rear"/>
    <axis xyz="0 1 0"/>
    <origin rpy="0.0 0 0" xyz="0.0 0.03 0.0"/>
    <dynamics damping="0.01" friction="0.0"/>
    <limit effort="0.5" velocity="0.05"/>
  </joint>
  <link name="omni_sphere1_left_rear">
    <inertial>
      <origin rpy="0 0 0" xyz="0.0 0.0 0.0"/>
      <mass value="0.05"/>
      <inertia ixx="0.000018" ixy="0" ixz="0" iyy="0.000018" iyz="0" izz="0.000018"/>
    </inertial>
    <visual>
      <origin rpy="0 0 0" xyz="0.0 0.0 0.0"/>
      <geometry>
        <sphere radius="0.03"/>
      </geometry>
      <material name="Blue">
        <color rgba="0.33 0.33 0.33 1.0"/>
      </material>
    </visual>
    <collision>
      <origin rpy="0 0 0" xyz="0.0 0.0 0.0"/>
      <geometry>
        <sphere radius="0.03"/>
      </geometry>
    </collision>
  </link>
  <gazebo reference="omni_sphere1_left_rear">
    <material>Gazebo/Blue</material>
    <turnGravityOff>false</turnGravityOff>
  </gazebo>
  <joint name="omni_sphere1_joint_right_rear" type="continuous">
    <parent link="wheel_right_rear"/>
    <child link="omni_sphere1_right_rear"/>
    <axis xyz="0 1 0"/>
    <origin rpy="0.0 0 0" xyz="0.0 0.03 0.0"/>
    <dynamics damping="0.01" friction="0.0"/>
    <limit effort="0.5" velocity="0.05"/>
  </joint>
  <link name="omni_sphere1_right_rear">
    <inertial>
      <origin rpy="0 0 0" xyz="0.0 0.0 0.0"/>
      <mass value="0.05"/>
      <inertia ixx="0.000018" ixy="0" ixz="0" iyy="0.000018" iyz="0" izz="0.000018"/>
    </inertial>
    <visual>
      <origin rpy="0 0 0" xyz="0.0 0.0 0.0"/>
      <geometry>
        <sphere radius="0.03"/>
      </geometry>
      <material name="Blue">
        <color rgba="0.33 0.33 0.33 1.0"/>
      </material>
    </visual>
    <collision>
      <origin rpy="0 0 0" xyz="0.0 0.0 0.0"/>
      <geometry>
        <sphere radius="0.03"/>
      </geometry>
    </collision>
  </link>
  <gazebo reference="omni_sphere1_right_rear">
    <material>Gazebo/Blue</material>
    <turnGravityOff>false</turnGravityOff>
  </gazebo>
  <joint name="omni_sphere2_joint_left_front" type="continuous">
    <parent link="wheel_left_front"/>
    <child link="omni_sphere2_left_front"/>
    <axis xyz="0 1 0"/>
    <origin rpy="0.5236 0 0" xyz="0.0 0.026 0.015"/>
    <dynamics damping="0.01" friction="0.0"/>
    <limit effort="0.5" velocity="0.05"/>
  </joint>
  <link name="omni_sphere2_left_front">
    <inertial>
      <origin rpy="0 0 0" xyz="0.0 0.0 0.0"/>
      <mass value="0.05"/>
      <inertia ixx="0.000018" ixy="0" ixz="0" iyy="0.000018" iyz="0" izz="0.000018"/>
    </inertial>
    <visual>
      <origin rpy="0 0 0" xyz="0.0 0.0 0.0"/>
      <geometry>
        <sphere radius="0.03"/>
      </geometry>
      <material name="Blue">
        <color rgba="0.33 0.33 0.33 1.0"/>
      </material>
    </visual>
    <collision>
      <origin rpy="0 0 0" xyz="0.0 0.0 0.0"/>
      <geometry>
        <sphere radius="0.03"/>
      </geometry>
    </collision>
  </link>
  <gazebo reference="omni_sphere2_left_front">
    <material>Gazebo/Blue</material>
    <turnGravityOff>false</turnGravityOff>
  </gazebo>
  <joint name="omni_sphere2_joint_right_front" type="continuous">
    <parent link="wheel_right_front"/>
    <child link="omni_sphere2_right_front"/>
    <axis xyz="0 1 0"/>
    <origin rpy="0.5236 0 0" xyz="0.0 0.026 0.015"/>
    <dynamics damping="0.01" friction="0.0"/>
    <limit effort="0.5" velocity="0.05"/>
  </joint>
  <link name="omni_sphere2_right_front">
    <inertial>
      <origin rpy="0 0 0" xyz="0.0 0.0 0.0"/>
      <mass value="0.05"/>
      <inertia ixx="0.000018" ixy="0" ixz="0" iyy="0.000018" iyz="0" izz="0.000018"/>
    </inertial>
    <visual>
      <origin rpy="0 0 0" xyz="0.0 0.0 0.0"/>
      <geometry>
        <sphere radius="0.03"/>
      </geometry>
      <material name="Blue">
        <color rgba="0.33 0.33 0.33 1.0"/>
      </material>
    </visual>
    <collision>
      <origin rpy="0 0 0" xyz="0.0 0.0 0.0"/>
      <geometry>
        <sphere radius="0.03"/>
      </geometry>
    </collision>
  </link>
  <gazebo reference="omni_sphere2_right_front">
    <material>Gazebo/Blue</material>
    <turnGravityOff>false</turnGravityOff>
  </gazebo>
  <joint name="omni_sphere2_joint_left_rear" type="continuous">
    <parent link="wheel_left_rear"/>
    <child link="omni_sphere2_left_rear"/>
    <axis xyz="0 1 0"/>
    <origin rpy="0.5236 0 0" xyz="0.0 0.026 0.015"/>
    <dynamics damping="0.01" friction="0.0"/>
    <limit effort="0.5" velocity="0.05"/>
  </joint>
  <link name="omni_sphere2_left_rear">
    <inertial>
      <origin rpy="0 0 0" xyz="0.0 0.0 0.0"/>
      <mass value="0.05"/>
      <inertia ixx="0.000018" ixy="0" ixz="0" iyy="0.000018" iyz="0" izz="0.000018"/>
    </inertial>
    <visual>
      <origin rpy="0 0 0" xyz="0.0 0.0 0.0"/>
      <geometry>
        <sphere radius="0.03"/>
      </geometry>
      <material name="Blue">
        <color rgba="0.33 0.33 0.33 1.0"/>
      </material>
    </visual>
    <collision>
      <origin rpy="0 0 0" xyz="0.0 0.0 0.0"/>
      <geometry>
        <sphere radius="0.03"/>
      </geometry>
    </collision>
  </link>
  <gazebo reference="omni_sphere2_left_rear">
    <material>Gazebo/Blue</material>
    <turnGravityOff>false</turnGravityOff>
  </gazebo>
  <joint name="omni_sphere2_joint_right_rear" type="continuous">
    <parent link="wheel_right_rear"/>
    <child link="omni_sphere2_right_rear"/>
    <axis xyz="0 1 0"/>
    <origin rpy="0.5236 0 0" xyz="0.0 0.026 0.015"/>
    <dynamics damping="0.01" friction="0.0"/>
    <limit effort="0.5" velocity="0.05"/>
  </joint>
  <link name="omni_sphere2_right_rear">
    <inertial>
      <origin rpy="0 0 0" xyz="0.0 0.0 0.0"/>
      <mass value="0.05"/>
      <inertia ixx="0.000018" ixy="0" ixz="0" iyy="0.000018" iyz="0" izz="0.000018"/>
    </inertial>
    <visual>
      <origin rpy="0 0 0" xyz="0.0 0.0 0.0"/>
      <geometry>
        <sphere radius="0.03"/>
      </geometry>
      <material name="Blue">
        <color rgba="0.33 0.33 0.33 1.0"/>
      </material>
    </visual>
    <collision>
      <origin rpy="0 0 0" xyz="0.0 0.0 0.0"/>
      <geometry>
        <sphere radius="0.03"/>
      </geometry>
    </collision>
  </link>
  <gazebo reference="omni_sphere2_right_rear">
    <material>Gazebo/Blue</material>
    <turnGravityOff>false</turnGravityOff>
  </gazebo>
  <joint name="omni_sphere3_joint_left_front" type="continuous">
    <parent link="wheel_left_front"/>
    <child link="omni_sphere3_left_front"/>
    <axis xyz="0 1 0"/>
    <origin rpy="1.0472 0 0" xyz="0.0 0.015 0.026"/>
    <dynamics damping="0.01" friction="0.0"/>
    <limit effort="0.5" velocity="0.05"/>
  </joint>
  <link name="omni_sphere3_left_front">
    <inertial>
      <origin rpy="0 0 0" xyz="0.0 0.0 0.0"/>
      <mass value="0.05"/>
      <inertia ixx="0.000018" ixy="0" ixz="0" iyy="0.000018" iyz="0" izz="0.000018"/>
    </inertial>
    <visual>
      <origin rpy="0 0 0" xyz="0.0 0.0 0.0"/>
      <geometry>
        <sphere radius="0.03"/>
      </geometry>
      <material name="Blue">
        <color rgba="0.33 0.33 0.33 1.0"/>
      </material>
    </visual>
    <collision>
      <origin rpy="0 0 0" xyz="0.0 0.0 0.0"/>
      <geometry>
        <sphere radius="0.03"/>
      </geometry>
    </collision>
  </link>
  <gazebo reference="omni_sphere3_left_front">
    <material>Gazebo/Blue</material>
    <turnGravityOff>false</turnGravityOff>
  </gazebo>
  <joint name="omni_sphere3_joint_right_front" type="continuous">
    <parent link="wheel_right_front"/>
    <child link="omni_sphere3_right_front"/>
    <axis xyz="0 1 0"/>
    <origin rpy="1.0472 0 0" xyz="0.0 0.015 0.026"/>
    <dynamics damping="0.01" friction="0.0"/>
    <limit effort="0.5" velocity="0.05"/>
  </joint>
  <link name="omni_sphere3_right_front">
    <inertial>
      <origin rpy="0 0 0" xyz="0.0 0.0 0.0"/>
      <mass value="0.05"/>
      <inertia ixx="0.000018" ixy="0" ixz="0" iyy="0.000018" iyz="0" izz="0.000018"/>
    </inertial>
    <visual>
      <origin rpy="0 0 0" xyz="0.0 0.0 0.0"/>
      <geometry>
        <sphere radius="0.03"/>
      </geometry>
      <material name="Blue">
        <color rgba="0.33 0.33 0.33 1.0"/>
      </material>
    </visual>
    <collision>
      <origin rpy="0 0 0" xyz="0.0 0.0 0.0"/>
      <geometry>
        <sphere radius="0.03"/>
      </geometry>
    </collision>
  </link>
  <gazebo reference="omni_sphere3_right_front">
    <material>Gazebo/Blue</material>
    <turnGravityOff>false</turnGravityOff>
  </gazebo>
  <joint name="omni_sphere3_joint_left_rear" type="continuous">
    <parent link="wheel_left_rear"/>
    <child link="omni_sphere3_left_rear"/>
    <axis xyz="0 1 0"/>
    <origin rpy="1.0472 0 0" xyz="0.0 0.015 0.026"/>
    <dynamics damping="0.01" friction="0.0"/>
    <limit effort="0.5" velocity="0.05"/>
  </joint>
  <link name="omni_sphere3_left_rear">
    <inertial>
      <origin rpy="0 0 0" xyz="0.0 0.0 0.0"/>
      <mass value="0.05"/>
      <inertia ixx="0.000018" ixy="0" ixz="0" iyy="0.000018" iyz="0" izz="0.000018"/>
    </inertial>
    <visual>
      <origin rpy="0 0 0" xyz="0.0 0.0 0.0"/>
      <geometry>
        <sphere radius="0.03"/>
      </geometry>
      <material name="Blue">
        <color rgba="0.33 0.33 0.33 1.0"/>
      </material>
    </visual>
    <collision>
      <origin rpy="0 0 0" xyz="0.0 0.0 0.0"/>
      <geometry>
        <sphere radius="0.03"/>
      </geometry>
    </collision>
  </link>
  <gazebo reference="omni_sphere3_left_rear">
    <material>Gazebo/Blue</material>
    <turnGravityOff>false</turnGravityOff>
  </gazebo>
  <joint name="omni_sphere3_joint_right_rear" type="continuous">
    <parent link="wheel_right_rear"/>
    <child link="omni_sphere3_right_rear"/>
    <axis xyz="0 1 0"/>
    <origin rpy="1.0472 0 0" xyz="0.0 0.015 0.026"/>
    <dynamics damping="0.01" friction="0.0"/>
    <limit effort="0.5" velocity="0.05"/>
  </joint>
  <link name="omni_sphere3_right_rear">
    <inertial>
      <origin rpy="0 0 0" xyz="0.0 0.0 0.0"/>
      <mass value="0.05"/>
      <inertia ixx="0.000018" ixy="0" ixz="0" iyy="0.000018" iyz="0" izz="0.000018"/>
    </inertial>
    <visual>
      <origin rpy="0 0 0" xyz="0.0 0.0 0.0"/>
      <geometry>
        <sphere radius="0.03"/>
      </geometry>
      <material name="Blue">
        <color rgba="0.33 0.33 0.33 1.0"/>
      </material>
    </visual>
    <collision>
      <origin rpy="0 0 0" xyz="0.0 0.0 0.0"/>
      <geometry>
        <sphere radius="0.03"/>
      </geometry>
    </collision>
  </link>
  <gazebo reference="omni_sphere3_right_rear">
    <material>Gazebo/Blue</material>
    <turnGravityOff>false</turnGravityOff>
  </gazebo>
  <joint name="omni_sphere4_joint_left_front" type="continuous">
    <parent link="wheel_left_front"/>
    <child link="omni_sphere4_left_front"/>
    <axis xyz="0 1 0"/>
    <origin rpy="1.5708 0 0" xyz="0.0 0 0.03"/>
    <dynamics damping="0.01" friction="0.0"/>
    <limit effort="0.5" velocity="0.05"/>
  </joint>
  <link name="omni_sphere4_left_front">
    <inertial>
      <origin rpy="0 0 0" xyz="0.0 0.0 0.0"/>
      <mass value="0.05"/>
      <inertia ixx="0.000018" ixy="0" ixz="0" iyy="0.000018" iyz="0" izz="0.000018"/>
    </inertial>
    <visual>
      <origin rpy="0 0 0" xyz="0.0 0.0 0.0"/>
      <geometry>
        <sphere radius="0.03"/>
      </geometry>
      <material name="Blue">
        <color rgba="0.33 0.33 0.33 1.0"/>
      </material>
    </visual>
    <collision>
      <origin rpy="0 0 0" xyz="0.0 0.0 0.0"/>
      <geometry>
        <sphere radius="0.03"/>
      </geometry>
    </collision>
  </link>
  <gazebo reference="omni_sphere4_left_front">
    <material>Gazebo/Blue</material>
    <turnGravityOff>false</turnGravityOff>
  </gazebo>
  <joint name="omni_sphere4_joint_right_front" type="continuous">
    <parent link="wheel_right_front"/>
    <child link="omni_sphere4_right_front"/>
    <axis xyz="0 1 0"/>
    <origin rpy="1.5708 0 0" xyz="0.0 0 0.03"/>
    <dynamics damping="0.01" friction="0.0"/>
    <limit effort="0.5" velocity="0.05"/>
  </joint>
  <link name="omni_sphere4_right_front">
    <inertial>
      <origin rpy="0 0 0" xyz="0.0 0.0 0.0"/>
      <mass value="0.05"/>
      <inertia ixx="0.000018" ixy="0" ixz="0" iyy="0.000018" iyz="0" izz="0.000018"/>
    </inertial>
    <visual>
      <origin rpy="0 0 0" xyz="0.0 0.0 0.0"/>
      <geometry>
        <sphere radius="0.03"/>
      </geometry>
      <material name="Blue">
        <color rgba="0.33 0.33 0.33 1.0"/>
      </material>
    </visual>
    <collision>
      <origin rpy="0 0 0" xyz="0.0 0.0 0.0"/>
      <geometry>
        <sphere radius="0.03"/>
      </geometry>
    </collision>
  </link>
  <gazebo reference="omni_sphere4_right_front">
    <material>Gazebo/Blue</material>
    <turnGravityOff>false</turnGravityOff>
  </gazebo>
  <joint name="omni_sphere4_joint_left_rear" type="continuous">
    <parent link="wheel_left_rear"/>
    <child link="omni_sphere4_left_rear"/>
    <axis xyz="0 1 0"/>
    <origin rpy="1.5708 0 0" xyz="0.0 0 0.03"/>
    <dynamics damping="0.01" friction="0.0"/>
    <limit effort="0.5" velocity="0.05"/>
  </joint>
  <link name="omni_sphere4_left_rear">
    <inertial>
      <origin rpy="0 0 0" xyz="0.0 0.0 0.0"/>
      <mass value="0.05"/>
      <inertia ixx="0.000018" ixy="0" ixz="0" iyy="0.000018" iyz="0" izz="0.000018"/>
    </inertial>
    <visual>
      <origin rpy="0 0 0" xyz="0.0 0.0 0.0"/>
      <geometry>
        <sphere radius="0.03"/>
      </geometry>
      <material name="Blue">
        <color rgba="0.33 0.33 0.33 1.0"/>
      </material>
    </visual>
    <collision>
      <origin rpy="0 0 0" xyz="0.0 0.0 0.0"/>
      <geometry>
        <sphere radius="0.03"/>
      </geometry>
    </collision>
  </link>
  <gazebo reference="omni_sphere4_left_rear">
    <material>Gazebo/Blue</material>
    <turnGravityOff>false</turnGravityOff>
  </gazebo>
  <joint name="omni_sphere4_joint_right_rear" type="continuous">
    <parent link="wheel_right_rear"/>
    <child link="omni_sphere4_right_rear"/>
    <axis xyz="0 1 0"/>
    <origin rpy="1.5708 0 0" xyz="0.0 0 0.03"/>
    <dynamics damping="0.01" friction="0.0"/>
    <limit effort="0.5" velocity="0.05"/>
  </joint>
  <link name="omni_sphere4_right_rear">
    <inertial>
      <origin rpy="0 0 0" xyz="0.0 0.0 0.0"/>
      <mass value="0.05"/>
      <inertia ixx="0.000018" ixy="0" ixz="0" iyy="0.000018" iyz="0" izz="0.000018"/>
    </inertial>
    <visual>
      <origin rpy="0 0 0" xyz="0.0 0.0 0.0"/>
      <geometry>
        <sphere radius="0.03"/>
      </geometry>
      <material name="Blue">
        <color rgba="0.33 0.33 0.33 1.0"/>
      </material>
    </visual>
    <collision>
      <origin rpy="0 0 0" xyz="0.0 0.0 0.0"/>
      <geometry>
        <sphere radius="0.03"/>
      </geometry>
    </collision>
  </link>
  <gazebo reference="omni_sphere4_right_rear">
    <material>Gazebo/Blue</material>
    <turnGravityOff>false</turnGravityOff>
  </gazebo>
  <joint name="omni_sphere5_joint_left_front" type="continuous">
    <parent link="wheel_left_front"/>
    <child link="omni_sphere5_left_front"/>
    <axis xyz="0 1 0"/>
    <origin rpy="2.0944 0 0" xyz="0.0 -0.015 0.026"/>
    <dynamics damping="0.01" friction="0.0"/>
    <limit effort="0.5" velocity="0.05"/>
  </joint>
  <link name="omni_sphere5_left_front">
    <inertial>
      <origin rpy="0 0 0" xyz="0.0 0.0 0.0"/>
      <mass value="0.05"/>
      <inertia ixx="0.000018" ixy="0" ixz="0" iyy="0.000018" iyz="0" izz="0.000018"/>
    </inertial>
    <visual>
      <origin rpy="0 0 0" xyz="0.0 0.0 0.0"/>
      <geometry>
        <sphere radius="0.03"/>
      </geometry>
      <material name="Blue">
        <color rgba="0.33 0.33 0.33 1.0"/>
      </material>
    </visual>
    <collision>
      <origin rpy="0 0 0" xyz="0.0 0.0 0.0"/>
      <geometry>
        <sphere radius="0.03"/>
      </geometry>
    </collision>
  </link>
  <gazebo reference="omni_sphere5_left_front">
    <material>Gazebo/Blue</material>
    <turnGravityOff>false</turnGravityOff>
  </gazebo>
  <joint name="omni_sphere5_joint_right_front" type="continuous">
    <parent link="wheel_right_front"/>
    <child link="omni_sphere5_right_front"/>
    <axis xyz="0 1 0"/>
    <origin rpy="2.0944 0 0" xyz="0.0 -0.015 0.026"/>
    <dynamics damping="0.01" friction="0.0"/>
    <limit effort="0.5" velocity="0.05"/>
  </joint>
  <link name="omni_sphere5_right_front">
    <inertial>
      <origin rpy="0 0 0" xyz="0.0 0.0 0.0"/>
      <mass value="0.05"/>
      <inertia ixx="0.000018" ixy="0" ixz="0" iyy="0.000018" iyz="0" izz="0.000018"/>
    </inertial>
    <visual>
      <origin rpy="0 0 0" xyz="0.0 0.0 0.0"/>
      <geometry>
        <sphere radius="0.03"/>
      </geometry>
      <material name="Blue">
        <color rgba="0.33 0.33 0.33 1.0"/>
      </material>
    </visual>
    <collision>
      <origin rpy="0 0 0" xyz="0.0 0.0 0.0"/>
      <geometry>
        <sphere radius="0.03"/>
      </geometry>
    </collision>
  </link>
  <gazebo reference="omni_sphere5_right_front">
    <material>Gazebo/Blue</material>
    <turnGravityOff>false</turnGravityOff>
  </gazebo>
  <joint name="omni_sphere5_joint_left_rear" type="continuous">
    <parent link="wheel_left_rear"/>
    <child link="omni_sphere5_left_rear"/>
    <axis xyz="0 1 0"/>
    <origin rpy="2.0944 0 0" xyz="0.0 -0.015 0.026"/>
    <dynamics damping="0.01" friction="0.0"/>
    <limit effort="0.5" velocity="0.05"/>
  </joint>
  <link name="omni_sphere5_left_rear">
    <inertial>
      <origin rpy="0 0 0" xyz="0.0 0.0 0.0"/>
      <mass value="0.05"/>
      <inertia ixx="0.000018" ixy="0" ixz="0" iyy="0.000018" iyz="0" izz="0.000018"/>
    </inertial>
    <visual>
      <origin rpy="0 0 0" xyz="0.0 0.0 0.0"/>
      <geometry>
        <sphere radius="0.03"/>
      </geometry>
      <material name="Blue">
        <color rgba="0.33 0.33 0.33 1.0"/>
      </material>
    </visual>
    <collision>
      <origin rpy="0 0 0" xyz="0.0 0.0 0.0"/>
      <geometry>
        <sphere radius="0.03"/>
      </geometry>
    </collision>
  </link>
  <gazebo reference="omni_sphere5_left_rear">
    <material>Gazebo/Blue</material>
    <turnGravityOff>false</turnGravityOff>
  </gazebo>
  <joint name="omni_sphere5_joint_right_rear" type="continuous">
    <parent link="wheel_right_rear"/>
    <child link="omni_sphere5_right_rear"/>
    <axis xyz="0 1 0"/>
    <origin rpy="2.0944 0 0" xyz="0.0 -0.015 0.026"/>
    <dynamics damping="0.01" friction="0.0"/>
    <limit effort="0.5" velocity="0.05"/>
  </joint>
  <link name="omni_sphere5_right_rear">
    <inertial>
      <origin rpy="0 0 0" xyz="0.0 0.0 0.0"/>
      <mass value="0.05"/>
      <inertia ixx="0.000018" ixy="0" ixz="0" iyy="0.000018" iyz="0" izz="0.000018"/>
    </inertial>
    <visual>
      <origin rpy="0 0 0" xyz="0.0 0.0 0.0"/>
      <geometry>
        <sphere radius="0.03"/>
      </geometry>
      <material name="Blue">
        <color rgba="0.33 0.33 0.33 1.0"/>
      </material>
    </visual>
    <collision>
      <origin rpy="0 0 0" xyz="0.0 0.0 0.0"/>
      <geometry>
        <sphere radius="0.03"/>
      </geometry>
    </collision>
  </link>
  <gazebo reference="omni_sphere5_right_rear">
    <material>Gazebo/Blue</material>
    <turnGravityOff>false</turnGravityOff>
  </gazebo>
  <joint name="omni_sphere6_joint_left_front" type="continuous">
    <parent link="wheel_left_front"/>
    <child link="omni_sphere6_left_front"/>
    <axis xyz="0 1 0"/>
    <origin rpy="2.618 0 0" xyz="0.0 -0.026 0.015"/>
    <dynamics damping="0.01" friction="0.0"/>
    <limit effort="0.5" velocity="0.05"/>
  </joint>
  <link name="omni_sphere6_left_front">
    <inertial>
      <origin rpy="0 0 0" xyz="0.0 0.0 0.0"/>
      <mass value="0.05"/>
      <inertia ixx="0.000018" ixy="0" ixz="0" iyy="0.000018" iyz="0" izz="0.000018"/>
    </inertial>
    <visual>
      <origin rpy="0 0 0" xyz="0.0 0.0 0.0"/>
      <geometry>
        <sphere radius="0.03"/>
      </geometry>
      <material name="Blue">
        <color rgba="0.33 0.33 0.33 1.0"/>
      </material>
    </visual>
    <collision>
      <origin rpy="0 0 0" xyz="0.0 0.0 0.0"/>
      <geometry>
        <sphere radius="0.03"/>
      </geometry>
    </collision>
  </link>
  <gazebo reference="omni_sphere6_left_front">
    <material>Gazebo/Blue</material>
    <turnGravityOff>false</turnGravityOff>
  </gazebo>
  <joint name="omni_sphere6_joint_right_front" type="continuous">
    <parent link="wheel_right_front"/>
    <child link="omni_sphere6_right_front"/>
    <axis xyz="0 1 0"/>
    <origin rpy="2.618 0 0" xyz="0.0 -0.026 0.015"/>
    <dynamics damping="0.01" friction="0.0"/>
    <limit effort="0.5" velocity="0.05"/>
  </joint>
  <link name="omni_sphere6_right_front">
    <inertial>
      <origin rpy="0 0 0" xyz="0.0 0.0 0.0"/>
      <mass value="0.05"/>
      <inertia ixx="0.000018" ixy="0" ixz="0" iyy="0.000018" iyz="0" izz="0.000018"/>
    </inertial>
    <visual>
      <origin rpy="0 0 0" xyz="0.0 0.0 0.0"/>
      <geometry>
        <sphere radius="0.03"/>
      </geometry>
      <material name="Blue">
        <color rgba="0.33 0.33 0.33 1.0"/>
      </material>
    </visual>
    <collision>
      <origin rpy="0 0 0" xyz="0.0 0.0 0.0"/>
      <geometry>
        <sphere radius="0.03"/>
      </geometry>
    </collision>
  </link>
  <gazebo reference="omni_sphere6_right_front">
    <material>Gazebo/Blue</material>
    <turnGravityOff>false</turnGravityOff>
  </gazebo>
  <joint name="omni_sphere6_joint_left_rear" type="continuous">
    <parent link="wheel_left_rear"/>
    <child link="omni_sphere6_left_rear"/>
    <axis xyz="0 1 0"/>
    <origin rpy="2.618 0 0" xyz="0.0 -0.026 0.015"/>
    <dynamics damping="0.01" friction="0.0"/>
    <limit effort="0.5" velocity="0.05"/>
  </joint>
  <link name="omni_sphere6_left_rear">
    <inertial>
      <origin rpy="0 0 0" xyz="0.0 0.0 0.0"/>
      <mass value="0.05"/>
      <inertia ixx="0.000018" ixy="0" ixz="0" iyy="0.000018" iyz="0" izz="0.000018"/>
    </inertial>
    <visual>
      <origin rpy="0 0 0" xyz="0.0 0.0 0.0"/>
      <geometry>
        <sphere radius="0.03"/>
      </geometry>
      <material name="Blue">
        <color rgba="0.33 0.33 0.33 1.0"/>
      </material>
    </visual>
    <collision>
      <origin rpy="0 0 0" xyz="0.0 0.0 0.0"/>
      <geometry>
        <sphere radius="0.03"/>
      </geometry>
    </collision>
  </link>
  <gazebo reference="omni_sphere6_left_rear">
    <material>Gazebo/Blue</material>
    <turnGravityOff>false</turnGravityOff>
  </gazebo>
  <joint name="omni_sphere6_joint_right_rear" type="continuous">
    <parent link="wheel_right_rear"/>
    <child link="omni_sphere6_right_rear"/>
    <axis xyz="0 1 0"/>
    <origin rpy="2.618 0 0" xyz="0.0 -0.026 0.015"/>
    <dynamics damping="0.01" friction="0.0"/>
    <limit effort="0.5" velocity="0.05"/>
  </joint>
  <link name="omni_sphere6_right_rear">
    <inertial>
      <origin rpy="0 0 0" xyz="0.0 0.0 0.0"/>
      <mass value="0.05"/>
      <inertia ixx="0.000018" ixy="0" ixz="0" iyy="0.000018" iyz="0" izz="0.000018"/>
    </inertial>
    <visual>
      <origin rpy="0 0 0" xyz="0.0 0.0 0.0"/>
      <geometry>
        <sphere radius="0.03"/>
      </geometry>
      <material name="Blue">
        <color rgba="0.33 0.33 0.33 1.0"/>
      </material>
    </visual>
    <collision>
      <origin rpy="0 0 0" xyz="0.0 0.0 0.0"/>
      <geometry>
        <sphere radius="0.03"/>
      </geometry>
    </collision>
  </link>
  <gazebo reference="omni_sphere6_right_rear">
    <material>Gazebo/Blue</material>
    <turnGravityOff>false</turnGravityOff>
  </gazebo>
  <joint name="omni_sphere7_joint_left_front" type="continuous">
    <parent link="wheel_left_front"/>
    <child link="omni_sphere7_left_front"/>
    <axis xyz="0 1 0"/>
    <origin rpy="3.1416 0 0" xyz="0.0 -0.03 0.0"/>
    <dynamics damping="0.01" friction="0.0"/>
    <limit effort="0.5" velocity="0.05"/>
  </joint>
  <link name="omni_sphere7_left_front">
    <inertial>
      <origin rpy="0 0 0" xyz="0.0 0.0 0.0"/>
      <mass value="0.05"/>
      <inertia ixx="0.000018" ixy="0" ixz="0" iyy="0.000018" iyz="0" izz="0.000018"/>
    </inertial>
    <visual>
      <origin rpy="0 0 0" xyz="0.0 0.0 0.0"/>
      <geometry>
        <sphere radius="0.03"/>
      </geometry>
      <material name="Blue">
        <color rgba="0.33 0.33 0.33 1.0"/>
      </material>
    </visual>
    <collision>
      <origin rpy="0 0 0" xyz="0.0 0.0 0.0"/>
      <geometry>
        <sphere radius="0.03"/>
      </geometry>
    </collision>
  </link>
  <gazebo reference="omni_sphere7_left_front">
    <material>Gazebo/Blue</material>
    <turnGravityOff>false</turnGravityOff>
  </gazebo>
  <joint name="omni_sphere7_joint_right_front" type="continuous">
    <parent link="wheel_right_front"/>
    <child link="omni_sphere7_right_front"/>
    <axis xyz="0 1 0"/>
    <origin rpy="3.1416 0 0" xyz="0.0 -0.03 0.0"/>
    <dynamics damping="0.01" friction="0.0"/>
    <limit effort="0.5" velocity="0.05"/>
  </joint>
  <link name="omni_sphere7_right_front">
    <inertial>
      <origin rpy="0 0 0" xyz="0.0 0.0 0.0"/>
      <mass value="0.05"/>
      <inertia ixx="0.000018" ixy="0" ixz="0" iyy="0.000018" iyz="0" izz="0.000018"/>
    </inertial>
    <visual>
      <origin rpy="0 0 0" xyz="0.0 0.0 0.0"/>
      <geometry>
        <sphere radius="0.03"/>
      </geometry>
      <material name="Blue">
        <color rgba="0.33 0.33 0.33 1.0"/>
      </material>
    </visual>
    <collision>
      <origin rpy="0 0 0" xyz="0.0 0.0 0.0"/>
      <geometry>
        <sphere radius="0.03"/>
      </geometry>
    </collision>
  </link>
  <gazebo reference="omni_sphere7_right_front">
    <material>Gazebo/Blue</material>
    <turnGravityOff>false</turnGravityOff>
  </gazebo>
  <joint name="omni_sphere7_joint_left_rear" type="continuous">
    <parent link="wheel_left_rear"/>
    <child link="omni_sphere7_left_rear"/>
    <axis xyz="0 1 0"/>
    <origin rpy="3.1416 0 0" xyz="0.0 -0.03 0.0"/>
    <dynamics damping="0.01" friction="0.0"/>
    <limit effort="0.5" velocity="0.05"/>
  </joint>
  <link name="omni_sphere7_left_rear">
    <inertial>
      <origin rpy="0 0 0" xyz="0.0 0.0 0.0"/>
      <mass value="0.05"/>
      <inertia ixx="0.000018" ixy="0" ixz="0" iyy="0.000018" iyz="0" izz="0.000018"/>
    </inertial>
    <visual>
      <origin rpy="0 0 0" xyz="0.0 0.0 0.0"/>
      <geometry>
        <sphere radius="0.03"/>
      </geometry>
      <material name="Blue">
        <color rgba="0.33 0.33 0.33 1.0"/>
      </material>
    </visual>
    <collision>
      <origin rpy="0 0 0" xyz="0.0 0.0 0.0"/>
      <geometry>
        <sphere radius="0.03"/>
      </geometry>
    </collision>
  </link>
  <gazebo reference="omni_sphere7_left_rear">
    <material>Gazebo/Blue</material>
    <turnGravityOff>false</turnGravityOff>
  </gazebo>
  <joint name="omni_sphere7_joint_right_rear" type="continuous">
    <parent link="wheel_right_rear"/>
    <child link="omni_sphere7_right_rear"/>
    <axis xyz="0 1 0"/>
    <origin rpy="3.1416 0 0" xyz="0.0 -0.03 0.0"/>
    <dynamics damping="0.01" friction="0.0"/>
    <limit effort="0.5" velocity="0.05"/>
  </joint>
  <link name="omni_sphere7_right_rear">
    <inertial>
      <origin rpy="0 0 0" xyz="0.0 0.0 0.0"/>
      <mass value="0.05"/>
      <inertia ixx="0.000018" ixy="0" ixz="0" iyy="0.000018" iyz="0" izz="0.000018"/>
    </inertial>
    <visual>
      <origin rpy="0 0 0" xyz="0.0 0.0 0.0"/>
      <geometry>
        <sphere radius="0.03"/>
      </geometry>
      <material name="Blue">
        <color rgba="0.33 0.33 0.33 1.0"/>
      </material>
    </visual>
    <collision>
      <origin rpy="0 0 0" xyz="0.0 0.0 0.0"/>
      <geometry>
        <sphere radius="0.03"/>
      </geometry>
    </collision>
  </link>
  <gazebo reference="omni_sphere7_right_rear">
    <material>Gazebo/Blue</material>
    <turnGravityOff>false</turnGravityOff>
  </gazebo>
  <joint name="omni_sphere8_joint_left_front" type="continuous">
    <parent link="wheel_left_front"/>
    <child link="omni_sphere8_left_front"/>
    <axis xyz="0 1 0"/>
    <origin rpy="3.6652 0 0" xyz="0.0 -0.026 -0.015"/>
    <dynamics damping="0.01" friction="0.0"/>
    <limit effort="0.5" velocity="0.05"/>
  </joint>
  <link name="omni_sphere8_left_front">
    <inertial>
      <origin rpy="0 0 0" xyz="0.0 0.0 0.0"/>
      <mass value="0.05"/>
      <inertia ixx="0.000018" ixy="0" ixz="0" iyy="0.000018" iyz="0" izz="0.000018"/>
    </inertial>
    <visual>
      <origin rpy="0 0 0" xyz="0.0 0.0 0.0"/>
      <geometry>
        <sphere radius="0.03"/>
      </geometry>
      <material name="Blue">
        <color rgba="0.33 0.33 0.33 1.0"/>
      </material>
    </visual>
    <collision>
      <origin rpy="0 0 0" xyz="0.0 0.0 0.0"/>
      <geometry>
        <sphere radius="0.03"/>
      </geometry>
    </collision>
  </link>
  <gazebo reference="omni_sphere8_left_front">
    <material>Gazebo/Blue</material>
    <turnGravityOff>false</turnGravityOff>
  </gazebo>
  <joint name="omni_sphere8_joint_right_front" type="continuous">
    <parent link="wheel_right_front"/>
    <child link="omni_sphere8_right_front"/>
    <axis xyz="0 1 0"/>
    <origin rpy="3.6652 0 0" xyz="0.0 -0.026 -0.015"/>
    <dynamics damping="0.01" friction="0.0"/>
    <limit effort="0.5" velocity="0.05"/>
  </joint>
  <link name="omni_sphere8_right_front">
    <inertial>
      <origin rpy="0 0 0" xyz="0.0 0.0 0.0"/>
      <mass value="0.05"/>
      <inertia ixx="0.000018" ixy="0" ixz="0" iyy="0.000018" iyz="0" izz="0.000018"/>
    </inertial>
    <visual>
      <origin rpy="0 0 0" xyz="0.0 0.0 0.0"/>
      <geometry>
        <sphere radius="0.03"/>
      </geometry>
      <material name="Blue">
        <color rgba="0.33 0.33 0.33 1.0"/>
      </material>
    </visual>
    <collision>
      <origin rpy="0 0 0" xyz="0.0 0.0 0.0"/>
      <geometry>
        <sphere radius="0.03"/>
      </geometry>
    </collision>
  </link>
  <gazebo reference="omni_sphere8_right_front">
    <material>Gazebo/Blue</material>
    <turnGravityOff>false</turnGravityOff>
  </gazebo>
  <joint name="omni_sphere8_joint_left_rear" type="continuous">
    <parent link="wheel_left_rear"/>
    <child link="omni_sphere8_left_rear"/>
    <axis xyz="0 1 0"/>
    <origin rpy="3.6652 0 0" xyz="0.0 -0.026 -0.015"/>
    <dynamics damping="0.01" friction="0.0"/>
    <limit effort="0.5" velocity="0.05"/>
  </joint>
  <link name="omni_sphere8_left_rear">
    <inertial>
      <origin rpy="0 0 0" xyz="0.0 0.0 0.0"/>
      <mass value="0.05"/>
      <inertia ixx="0.000018" ixy="0" ixz="0" iyy="0.000018" iyz="0" izz="0.000018"/>
    </inertial>
    <visual>
      <origin rpy="0 0 0" xyz="0.0 0.0 0.0"/>
      <geometry>
        <sphere radius="0.03"/>
      </geometry>
      <material name="Blue">
        <color rgba="0.33 0.33 0.33 1.0"/>
      </material>
    </visual>
    <collision>
      <origin rpy="0 0 0" xyz="0.0 0.0 0.0"/>
      <geometry>
        <sphere radius="0.03"/>
      </geometry>
    </collision>
  </link>
  <gazebo reference="omni_sphere8_left_rear">
    <material>Gazebo/Blue</material>
    <turnGravityOff>false</turnGravityOff>
  </gazebo>
  <joint name="omni_sphere8_joint_right_rear" type="continuous">
    <parent link="wheel_right_rear"/>
    <child link="omni_sphere8_right_rear"/>
    <axis xyz="0 1 0"/>
    <origin rpy="3.6652 0 0" xyz="0.0 -0.026 -0.015"/>
    <dynamics damping="0.01" friction="0.0"/>
    <limit effort="0.5" velocity="0.05"/>
  </joint>
  <link name="omni_sphere8_right_rear">
    <inertial>
      <origin rpy="0 0 0" xyz="0.0 0.0 0.0"/>
      <mass value="0.05"/>
      <inertia ixx="0.000018" ixy="0" ixz="0" iyy="0.000018" iyz="0" izz="0.000018"/>
    </inertial>
    <visual>
      <origin rpy="0 0 0" xyz="0.0 0.0 0.0"/>
      <geometry>
        <sphere radius="0.03"/>
      </geometry>
      <material name="Blue">
        <color rgba="0.33 0.33 0.33 1.0"/>
      </material>
    </visual>
    <collision>
      <origin rpy="0 0 0" xyz="0.0 0.0 0.0"/>
      <geometry>
        <sphere radius="0.03"/>
      </geometry>
    </collision>
  </link>
  <gazebo reference="omni_sphere8_right_rear">
    <material>Gazebo/Blue</material>
    <turnGravityOff>false</turnGravityOff>
  </gazebo>
  <joint name="omni_sphere9_joint_left_front" type="continuous">
    <parent link="wheel_left_front"/>
    <child link="omni_sphere9_left_front"/>
    <axis xyz="0 1 0"/>
    <origin rpy="4.1888 0 0" xyz="0.0 -0.015 -0.026"/>
    <dynamics damping="0.01" friction="0.0"/>
    <limit effort="0.5" velocity="0.05"/>
  </joint>
  <link name="omni_sphere9_left_front">
    <inertial>
      <origin rpy="0 0 0" xyz="0.0 0.0 0.0"/>
      <mass value="0.05"/>
      <inertia ixx="0.000018" ixy="0" ixz="0" iyy="0.000018" iyz="0" izz="0.000018"/>
    </inertial>
    <visual>
      <origin rpy="0 0 0" xyz="0.0 0.0 0.0"/>
      <geometry>
        <sphere radius="0.03"/>
      </geometry>
      <material name="Blue">
        <color rgba="0.33 0.33 0.33 1.0"/>
      </material>
    </visual>
    <collision>
      <origin rpy="0 0 0" xyz="0.0 0.0 0.0"/>
      <geometry>
        <sphere radius="0.03"/>
      </geometry>
    </collision>
  </link>
  <gazebo reference="omni_sphere9_left_front">
    <material>Gazebo/Blue</material>
    <turnGravityOff>false</turnGravityOff>
  </gazebo>
  <joint name="omni_sphere9_joint_right_front" type="continuous">
    <parent link="wheel_right_front"/>
    <child link="omni_sphere9_right_front"/>
    <axis xyz="0 1 0"/>
    <origin rpy="4.1888 0 0" xyz="0.0 -0.015 -0.026"/>
    <dynamics damping="0.01" friction="0.0"/>
    <limit effort="0.5" velocity="0.05"/>
  </joint>
  <link name="omni_sphere9_right_front">
    <inertial>
      <origin rpy="0 0 0" xyz="0.0 0.0 0.0"/>
      <mass value="0.05"/>
      <inertia ixx="0.000018" ixy="0" ixz="0" iyy="0.000018" iyz="0" izz="0.000018"/>
    </inertial>
    <visual>
      <origin rpy="0 0 0" xyz="0.0 0.0 0.0"/>
      <geometry>
        <sphere radius="0.03"/>
      </geometry>
      <material name="Blue">
        <color rgba="0.33 0.33 0.33 1.0"/>
      </material>
    </visual>
    <collision>
      <origin rpy="0 0 0" xyz="0.0 0.0 0.0"/>
      <geometry>
        <sphere radius="0.03"/>
      </geometry>
    </collision>
  </link>
  <gazebo reference="omni_sphere9_right_front">
    <material>Gazebo/Blue</material>
    <turnGravityOff>false</turnGravityOff>
  </gazebo>
  <joint name="omni_sphere9_joint_left_rear" type="continuous">
    <parent link="wheel_left_rear"/>
    <child link="omni_sphere9_left_rear"/>
    <axis xyz="0 1 0"/>
    <origin rpy="4.1888 0 0" xyz="0.0 -0.015 -0.026"/>
    <dynamics damping="0.01" friction="0.0"/>
    <limit effort="0.5" velocity="0.05"/>
  </joint>
  <link name="omni_sphere9_left_rear">
    <inertial>
      <origin rpy="0 0 0" xyz="0.0 0.0 0.0"/>
      <mass value="0.05"/>
      <inertia ixx="0.000018" ixy="0" ixz="0" iyy="0.000018" iyz="0" izz="0.000018"/>
    </inertial>
    <visual>
      <origin rpy="0 0 0" xyz="0.0 0.0 0.0"/>
      <geometry>
        <sphere radius="0.03"/>
      </geometry>
      <material name="Blue">
        <color rgba="0.33 0.33 0.33 1.0"/>
      </material>
    </visual>
    <collision>
      <origin rpy="0 0 0" xyz="0.0 0.0 0.0"/>
      <geometry>
        <sphere radius="0.03"/>
      </geometry>
    </collision>
  </link>
  <gazebo reference="omni_sphere9_left_rear">
    <material>Gazebo/Blue</material>
    <turnGravityOff>false</turnGravityOff>
  </gazebo>
  <joint name="omni_sphere9_joint_right_rear" type="continuous">
    <parent link="wheel_right_rear"/>
    <child link="omni_sphere9_right_rear"/>
    <axis xyz="0 1 0"/>
    <origin rpy="4.1888 0 0" xyz="0.0 -0.015 -0.026"/>
    <dynamics damping="0.01" friction="0.0"/>
    <limit effort="0.5" velocity="0.05"/>
  </joint>
  <link name="omni_sphere9_right_rear">
    <inertial>
      <origin rpy="0 0 0" xyz="0.0 0.0 0.0"/>
      <mass value="0.05"/>
      <inertia ixx="0.000018" ixy="0" ixz="0" iyy="0.000018" iyz="0" izz="0.000018"/>
    </inertial>
    <visual>
      <origin rpy="0 0 0" xyz="0.0 0.0 0.0"/>
      <geometry>
        <sphere radius="0.03"/>
      </geometry>
      <material name="Blue">
        <color rgba="0.33 0.33 0.33 1.0"/>
      </material>
    </visual>
    <collision>
      <origin rpy="0 0 0" xyz="0.0 0.0 0.0"/>
      <geometry>
        <sphere radius="0.03"/>
      </geometry>
    </collision>
  </link>
  <gazebo reference="omni_sphere9_right_rear">
    <material>Gazebo/Blue</material>
    <turnGravityOff>false</turnGravityOff>
  </gazebo>
  <joint name="omni_sphere10_joint_left_front" type="continuous">
    <parent link="wheel_left_front"/>
    <child link="omni_sphere10_left_front"/>
    <axis xyz="0 1 0"/>
    <origin rpy="4.7124 0 0" xyz="0.0 0.0 -0.03"/>
    <dynamics damping="0.01" friction="0.0"/>
    <limit effort="0.5" velocity="0.05"/>
  </joint>
  <link name="omni_sphere10_left_front">
    <inertial>
      <origin rpy="0 0 0" xyz="0.0 0.0 0.0"/>
      <mass value="0.05"/>
      <inertia ixx="0.000018" ixy="0" ixz="0" iyy="0.000018" iyz="0" izz="0.000018"/>
    </inertial>
    <visual>
      <origin rpy="0 0 0" xyz="0.0 0.0 0.0"/>
      <geometry>
        <sphere radius="0.03"/>
      </geometry>
      <material name="Blue">
        <color rgba="0.33 0.33 0.33 1.0"/>
      </material>
    </visual>
    <collision>
      <origin rpy="0 0 0" xyz="0.0 0.0 0.0"/>
      <geometry>
        <sphere radius="0.03"/>
      </geometry>
    </collision>
  </link>
  <gazebo reference="omni_sphere10_left_front">
    <material>Gazebo/Blue</material>
    <turnGravityOff>false</turnGravityOff>
  </gazebo>
  <joint name="omni_sphere10_joint_right_front" type="continuous">
    <parent link="wheel_right_front"/>
    <child link="omni_sphere10_right_front"/>
    <axis xyz="0 1 0"/>
    <origin rpy="4.7124 0 0" xyz="0.0 0.0 -0.03"/>
    <dynamics damping="0.01" friction="0.0"/>
    <limit effort="0.5" velocity="0.05"/>
  </joint>
  <link name="omni_sphere10_right_front">
    <inertial>
      <origin rpy="0 0 0" xyz="0.0 0.0 0.0"/>
      <mass value="0.05"/>
      <inertia ixx="0.000018" ixy="0" ixz="0" iyy="0.000018" iyz="0" izz="0.000018"/>
    </inertial>
    <visual>
      <origin rpy="0 0 0" xyz="0.0 0.0 0.0"/>
      <geometry>
        <sphere radius="0.03"/>
      </geometry>
      <material name="Blue">
        <color rgba="0.33 0.33 0.33 1.0"/>
      </material>
    </visual>
    <collision>
      <origin rpy="0 0 0" xyz="0.0 0.0 0.0"/>
      <geometry>
        <sphere radius="0.03"/>
      </geometry>
    </collision>
  </link>
  <gazebo reference="omni_sphere10_right_front">
    <material>Gazebo/Blue</material>
    <turnGravityOff>false</turnGravityOff>
  </gazebo>
  <joint name="omni_sphere10_joint_left_rear" type="continuous">
    <parent link="wheel_left_rear"/>
    <child link="omni_sphere10_left_rear"/>
    <axis xyz="0 1 0"/>
    <origin rpy="4.7124 0 0" xyz="0.0 0.0 -0.03"/>
    <dynamics damping="0.01" friction="0.0"/>
    <limit effort="0.5" velocity="0.05"/>
  </joint>
  <link name="omni_sphere10_left_rear">
    <inertial>
      <origin rpy="0 0 0" xyz="0.0 0.0 0.0"/>
      <mass value="0.05"/>
      <inertia ixx="0.000018" ixy="0" ixz="0" iyy="0.000018" iyz="0" izz="0.000018"/>
    </inertial>
    <visual>
      <origin rpy="0 0 0" xyz="0.0 0.0 0.0"/>
      <geometry>
        <sphere radius="0.03"/>
      </geometry>
      <material name="Blue">
        <color rgba="0.33 0.33 0.33 1.0"/>
      </material>
    </visual>
    <collision>
      <origin rpy="0 0 0" xyz="0.0 0.0 0.0"/>
      <geometry>
        <sphere radius="0.03"/>
      </geometry>
    </collision>
  </link>
  <gazebo reference="omni_sphere10_left_rear">
    <material>Gazebo/Blue</material>
    <turnGravityOff>false</turnGravityOff>
  </gazebo>
  <joint name="omni_sphere10_joint_right_rear" type="continuous">
    <parent link="wheel_right_rear"/>
    <child link="omni_sphere10_right_rear"/>
    <axis xyz="0 1 0"/>
    <origin rpy="4.7124 0 0" xyz="0.0 0.0 -0.03"/>
    <dynamics damping="0.01" friction="0.0"/>
    <limit effort="0.5" velocity="0.05"/>
  </joint>
  <link name="omni_sphere10_right_rear">
    <inertial>
      <origin rpy="0 0 0" xyz="0.0 0.0 0.0"/>
      <mass value="0.05"/>
      <inertia ixx="0.000018" ixy="0" ixz="0" iyy="0.000018" iyz="0" izz="0.000018"/>
    </inertial>
    <visual>
      <origin rpy="0 0 0" xyz="0.0 0.0 0.0"/>
      <geometry>
        <sphere radius="0.03"/>
      </geometry>
      <material name="Blue">
        <color rgba="0.33 0.33 0.33 1.0"/>
      </material>
    </visual>
    <collision>
      <origin rpy="0 0 0" xyz="0.0 0.0 0.0"/>
      <geometry>
        <sphere radius="0.03"/>
      </geometry>
    </collision>
  </link>
  <gazebo reference="omni_sphere10_right_rear">
    <material>Gazebo/Blue</material>
    <turnGravityOff>false</turnGravityOff>
  </gazebo>
  <joint name="omni_sphere11_joint_left_front" type="continuous">
    <parent link="wheel_left_front"/>
    <child link="omni_sphere11_left_front"/>
    <axis xyz="0 1 0"/>
    <origin rpy="5.236 0 0" xyz="0.0 0.015 -0.026"/>
    <dynamics damping="0.01" friction="0.0"/>
    <limit effort="0.5" velocity="0.05"/>
  </joint>
  <link name="omni_sphere11_left_front">
    <inertial>
      <origin rpy="0 0 0" xyz="0.0 0.0 0.0"/>
      <mass value="0.05"/>
      <inertia ixx="0.000018" ixy="0" ixz="0" iyy="0.000018" iyz="0" izz="0.000018"/>
    </inertial>
    <visual>
      <origin rpy="0 0 0" xyz="0.0 0.0 0.0"/>
      <geometry>
        <sphere radius="0.03"/>
      </geometry>
      <material name="Blue">
        <color rgba="0.33 0.33 0.33 1.0"/>
      </material>
    </visual>
    <collision>
      <origin rpy="0 0 0" xyz="0.0 0.0 0.0"/>
      <geometry>
        <sphere radius="0.03"/>
      </geometry>
    </collision>
  </link>
  <gazebo reference="omni_sphere11_left_front">
    <material>Gazebo/Blue</material>
    <turnGravityOff>false</turnGravityOff>
  </gazebo>
  <joint name="omni_sphere11_joint_right_front" type="continuous">
    <parent link="wheel_right_front"/>
    <child link="omni_sphere11_right_front"/>
    <axis xyz="0 1 0"/>
    <origin rpy="5.236 0 0" xyz="0.0 0.015 -0.026"/>
    <dynamics damping="0.01" friction="0.0"/>
    <limit effort="0.5" velocity="0.05"/>
  </joint>
  <link name="omni_sphere11_right_front">
    <inertial>
      <origin rpy="0 0 0" xyz="0.0 0.0 0.0"/>
      <mass value="0.05"/>
      <inertia ixx="0.000018" ixy="0" ixz="0" iyy="0.000018" iyz="0" izz="0.000018"/>
    </inertial>
    <visual>
      <origin rpy="0 0 0" xyz="0.0 0.0 0.0"/>
      <geometry>
        <sphere radius="0.03"/>
      </geometry>
      <material name="Blue">
        <color rgba="0.33 0.33 0.33 1.0"/>
      </material>
    </visual>
    <collision>
      <origin rpy="0 0 0" xyz="0.0 0.0 0.0"/>
      <geometry>
        <sphere radius="0.03"/>
      </geometry>
    </collision>
  </link>
  <gazebo reference="omni_sphere11_right_front">
    <material>Gazebo/Blue</material>
    <turnGravityOff>false</turnGravityOff>
  </gazebo>
  <joint name="omni_sphere11_joint_left_rear" type="continuous">
    <parent link="wheel_left_rear"/>
    <child link="omni_sphere11_left_rear"/>
    <axis xyz="0 1 0"/>
    <origin rpy="5.236 0 0" xyz="0.0 0.015 -0.026"/>
    <dynamics damping="0.01" friction="0.0"/>
    <limit effort="0.5" velocity="0.05"/>
  </joint>
  <link name="omni_sphere11_left_rear">
    <inertial>
      <origin rpy="0 0 0" xyz="0.0 0.0 0.0"/>
      <mass value="0.05"/>
      <inertia ixx="0.000018" ixy="0" ixz="0" iyy="0.000018" iyz="0" izz="0.000018"/>
    </inertial>
    <visual>
      <origin rpy="0 0 0" xyz="0.0 0.0 0.0"/>
      <geometry>
        <sphere radius="0.03"/>
      </geometry>
      <material name="Blue">
        <color rgba="0.33 0.33 0.33 1.0"/>
      </material>
    </visual>
    <collision>
      <origin rpy="0 0 0" xyz="0.0 0.0 0.0"/>
      <geometry>
        <sphere radius="0.03"/>
      </geometry>
    </collision>
  </link>
  <gazebo reference="omni_sphere11_left_rear">
    <material>Gazebo/Blue</material>
    <turnGravityOff>false</turnGravityOff>
  </gazebo>
  <joint name="omni_sphere11_joint_right_rear" type="continuous">
    <parent link="wheel_right_rear"/>
    <child link="omni_sphere11_right_rear"/>
    <axis xyz="0 1 0"/>
    <origin rpy="5.236 0 0" xyz="0.0 0.015 -0.026"/>
    <dynamics damping="0.01" friction="0.0"/>
    <limit effort="0.5" velocity="0.05"/>
  </joint>
  <link name="omni_sphere11_right_rear">
    <inertial>
      <origin rpy="0 0 0" xyz="0.0 0.0 0.0"/>
      <mass value="0.05"/>
      <inertia ixx="0.000018" ixy="0" ixz="0" iyy="0.000018" iyz="0" izz="0.000018"/>
    </inertial>
    <visual>
      <origin rpy="0 0 0" xyz="0.0 0.0 0.0"/>
      <geometry>
        <sphere radius="0.03"/>
      </geometry>
      <material name="Blue">
        <color rgba="0.33 0.33 0.33 1.0"/>
      </material>
    </visual>
    <collision>
      <origin rpy="0 0 0" xyz="0.0 0.0 0.0"/>
      <geometry>
        <sphere radius="0.03"/>
      </geometry>
    </collision>
  </link>
  <gazebo reference="omni_sphere11_right_rear">
    <material>Gazebo/Blue</material>
    <turnGravityOff>false</turnGravityOff>
  </gazebo>
  <joint name="omni_sphere12_joint_left_front" type="continuous">
    <parent link="wheel_left_front"/>
    <child link="omni_sphere12_left_front"/>
    <axis xyz="0 1 0"/>
    <origin rpy="5.7596 0 0" xyz="0.0 0.026 -0.015"/>
    <dynamics damping="0.01" friction="0.0"/>
    <limit effort="0.5" velocity="0.05"/>
  </joint>
  <link name="omni_sphere12_left_front">
    <inertial>
      <origin rpy="0 0 0" xyz="0.0 0.0 0.0"/>
      <mass value="0.05"/>
      <inertia ixx="0.000018" ixy="0" ixz="0" iyy="0.000018" iyz="0" izz="0.000018"/>
    </inertial>
    <visual>
      <origin rpy="0 0 0" xyz="0.0 0.0 0.0"/>
      <geometry>
        <sphere radius="0.03"/>
      </geometry>
      <material name="Blue">
        <color rgba="0.33 0.33 0.33 1.0"/>
      </material>
    </visual>
    <collision>
      <origin rpy="0 0 0" xyz="0.0 0.0 0.0"/>
      <geometry>
        <sphere radius="0.03"/>
      </geometry>
    </collision>
  </link>
  <gazebo reference="omni_sphere12_left_front">
    <material>Gazebo/Blue</material>
    <turnGravityOff>false</turnGravityOff>
  </gazebo>
  <joint name="omni_sphere12_joint_right_front" type="continuous">
    <parent link="wheel_right_front"/>
    <child link="omni_sphere12_right_front"/>
    <axis xyz="0 1 0"/>
    <origin rpy="5.7596 0 0" xyz="0.0 0.026 -0.015"/>
    <dynamics damping="0.01" friction="0.0"/>
    <limit effort="0.5" velocity="0.05"/>
  </joint>
  <link name="omni_sphere12_right_front">
    <inertial>
      <origin rpy="0 0 0" xyz="0.0 0.0 0.0"/>
      <mass value="0.05"/>
      <inertia ixx="0.000018" ixy="0" ixz="0" iyy="0.000018" iyz="0" izz="0.000018"/>
    </inertial>
    <visual>
      <origin rpy="0 0 0" xyz="0.0 0.0 0.0"/>
      <geometry>
        <sphere radius="0.03"/>
      </geometry>
      <material name="Blue">
        <color rgba="0.33 0.33 0.33 1.0"/>
      </material>
    </visual>
    <collision>
      <origin rpy="0 0 0" xyz="0.0 0.0 0.0"/>
      <geometry>
        <sphere radius="0.03"/>
      </geometry>
    </collision>
  </link>
  <gazebo reference="omni_sphere12_right_front">
    <material>Gazebo/Blue</material>
    <turnGravityOff>false</turnGravityOff>
  </gazebo>
  <joint name="omni_sphere12_joint_left_rear" type="continuous">
    <parent link="wheel_left_rear"/>
    <child link="omni_sphere12_left_rear"/>
    <axis xyz="0 1 0"/>
    <origin rpy="5.7596 0 0" xyz="0.0 0.026 -0.015"/>
    <dynamics damping="0.01" friction="0.0"/>
    <limit effort="0.5" velocity="0.05"/>
  </joint>
  <link name="omni_sphere12_left_rear">
    <inertial>
      <origin rpy="0 0 0" xyz="0.0 0.0 0.0"/>
      <mass value="0.05"/>
      <inertia ixx="0.000018" ixy="0" ixz="0" iyy="0.000018" iyz="0" izz="0.000018"/>
    </inertial>
    <visual>
      <origin rpy="0 0 0" xyz="0.0 0.0 0.0"/>
      <geometry>
        <sphere radius="0.03"/>
      </geometry>
      <material name="Blue">
        <color rgba="0.33 0.33 0.33 1.0"/>
      </material>
    </visual>
    <collision>
      <origin rpy="0 0 0" xyz="0.0 0.0 0.0"/>
      <geometry>
        <sphere radius="0.03"/>
      </geometry>
    </collision>
  </link>
  <gazebo reference="omni_sphere12_left_rear">
    <material>Gazebo/Blue</material>
    <turnGravityOff>false</turnGravityOff>
  </gazebo>
  <joint name="omni_sphere12_joint_right_rear" type="continuous">
    <parent link="wheel_right_rear"/>
    <child link="omni_sphere12_right_rear"/>
    <axis xyz="0 1 0"/>
    <origin rpy="5.7596 0 0" xyz="0.0 0.026 -0.015"/>
    <dynamics damping="0.01" friction="0.0"/>
    <limit effort="0.5" velocity="0.05"/>
  </joint>
  <link name="omni_sphere12_right_rear">
    <inertial>
      <origin rpy="0 0 0" xyz="0.0 0.0 0.0"/>
      <mass value="0.05"/>
      <inertia ixx="0.000018" ixy="0" ixz="0" iyy="0.000018" iyz="0" izz="0.000018"/>
    </inertial>
    <visual>
      <origin rpy="0 0 0" xyz="0.0 0.0 0.0"/>
      <geometry>
        <sphere radius="0.03"/>
      </geometry>
      <material name="Blue">
        <color rgba="0.33 0.33 0.33 1.0"/>
      </material>
    </visual>
    <collision>
      <origin rpy="0 0 0" xyz="0.0 0.0 0.0"/>
      <geometry>
        <sphere radius="0.03"/>
      </geometry>
    </collision>
  </link>
  <gazebo reference="omni_sphere12_right_rear">
    <material>Gazebo/Blue</material>
    <turnGravityOff>false</turnGravityOff>
  </gazebo>
  <joint name="wheel_inner_joint_left_front" type="continuous">
    <parent link="base"/>
    <child link="wheel_left_front"/>
    <axis xyz="1 0 0"/>
    <origin rpy="0 0 2.3562" xyz="-0.25 +0.25 -0.3275"/>
    <dynamics damping="1" friction="0.0"/>
    <limit effort="5.0" velocity="5.0"/>
  </joint>
  <link name="wheel_left_front">
    <inertial>
      <origin rpy="0 0 0" xyz="0.0 0.0 0.0"/>
      <mass value="0.5"/>
      <inertia ixx="0.0006" ixy="0" ixz="0" iyy="0.0006" iyz="0" izz="0.0006"/>
    </inertial>
    <visual>
      <origin rpy="0 1.5708 0" xyz="0.0 0.0 0.0"/>
      <geometry>
        <cylinder length="0.05" radius="0.05"/>
      </geometry>
      <material name="Blue">
        <color rgba="0.33 0.33 0.33 1.0"/>
      </material>
    </visual>
    <collision>
      <origin rpy="0 1.5708 0" xyz="0.0 0.0 0.0"/>
      <geometry>
        <cylinder length="0.05" radius="0.05"/>
      </geometry>
    </collision>
  </link>
  <gazebo reference="wheel_left_front">
    <material>Gazebo/Blue</material>
    <turnGravityOff>false</turnGravityOff>
  </gazebo>
  <joint name="wheel_inner_joint_right_front" type="continuous">
    <parent link="base"/>
    <child link="wheel_right_front"/>
    <axis xyz="1 0 0"/>
    <origin rpy="0 0 0.7854" xyz="+0.25 +0.25 -0.3275"/>
    <dynamics damping="1" friction="0.0"/>
    <limit effort="5.0" velocity="5.0"/>
  </joint>
  <link name="wheel_right_front">
    <inertial>
      <origin rpy="0 0 0" xyz="0.0 0.0 0.0"/>
      <mass value="0.5"/>
      <inertia ixx="0.0006" ixy="0" ixz="0" iyy="0.0006" iyz="0" izz="0.0006"/>
    </inertial>
    <visual>
      <origin rpy="0 1.5708 0" xyz="0.0 0.0 0.0"/>
      <geometry>
        <cylinder length="0.05" radius="0.05"/>
      </geometry>
      <material name="Blue">
        <color rgba="0.33 0.33 0.33 1.0"/>
      </material>
    </visual>
    <collision>
      <origin rpy="0 1.5708 0" xyz="0.0 0.0 0.0"/>
      <geometry>
        <cylinder length="0.05" radius="0.05"/>
      </geometry>
    </collision>
  </link>
  <gazebo reference="wheel_right_front">
    <material>Gazebo/Blue</material>
    <turnGravityOff>false</turnGravityOff>
  </gazebo>
  <joint name="wheel_inner_joint_left_rear" type="continuous">
    <parent link="base"/>
    <child link="wheel_left_rear"/>
    <axis xyz="1 0 0"/>
    <origin rpy="0 0 -2.3562" xyz="-0.25 -0.25 -0.3275"/>
    <dynamics damping="1" friction="0.0"/>
    <limit effort="5.0" velocity="5.0"/>
  </joint>
  <link name="wheel_left_rear">
    <inertial>
      <origin rpy="0 0 0" xyz="0.0 0.0 0.0"/>
      <mass value="0.5"/>
      <inertia ixx="0.0006" ixy="0" ixz="0" iyy="0.0006" iyz="0" izz="0.0006"/>
    </inertial>
    <visual>
      <origin rpy="0 1.5708 0" xyz="0.0 0.0 0.0"/>
      <geometry>
        <cylinder length="0.05" radius="0.05"/>
      </geometry>
      <material name="Blue">
        <color rgba="0.33 0.33 0.33 1.0"/>
      </material>
    </visual>
    <collision>
      <origin rpy="0 1.5708 0" xyz="0.0 0.0 0.0"/>
      <geometry>
        <cylinder length="0.05" radius="0.05"/>
      </geometry>
    </collision>
  </link>
  <gazebo reference="wheel_left_rear">
    <material>Gazebo/Blue</material>
    <turnGravityOff>false</turnGravityOff>
  </gazebo>
  <joint name="wheel_inner_joint_right_rear" type="continuous">
    <parent link="base"/>
    <child link="wheel_right_rear"/>
    <axis xyz="1 0 0"/>
    <origin rpy="0 0 -0.7854" xyz="+0.25 -0.25 -0.3275"/>
    <dynamics damping="1" friction="0.0"/>
    <limit effort="5.0" velocity="5.0"/>
  </joint>
  <link name="wheel_right_rear">
    <inertial>
      <origin rpy="0 0 0" xyz="0.0 0.0 0.0"/>
      <mass value="0.5"/>
      <inertia ixx="0.0006" ixy="0" ixz="0" iyy="0.0006" iyz="0" izz="0.0006"/>
    </inertial>
    <visual>
      <origin rpy="0 1.5708 0" xyz="0.0 0.0 0.0"/>
      <geometry>
        <cylinder length="0.05" radius="0.05"/>
      </geometry>
      <material name="Blue">
        <color rgba="0.33 0.33 0.33 1.0"/>
      </material>
    </visual>
    <collision>
      <origin rpy="0 1.5708 0" xyz="0.0 0.0 0.0"/>
      <geometry>
        <cylinder length="0.05" radius="0.05"/>
      </geometry>
    </collision>
  </link>
  <gazebo reference="wheel_right_rear">
    <material>Gazebo/Blue</material>
    <turnGravityOff>false</turnGravityOff>
  </gazebo>
  <!--========BUILD ARMS======-->
  <link name="shoulder_link1_left">
    <inertial>
      <origin rpy="0 0 0" xyz="0.0 0.0 0.0"/>
      <mass value="0.1"/>
      <inertia ixx="0.01" ixy="0" ixz="0" iyy="0.01" iyz="0" izz="0.01"/>
    </inertial>
    <visual>
      <origin rpy="0 0 0 " xyz="0.0 0.0 0.0"/>
      <geometry>
        <cylinder length="0.105" radius="0.04"/>
      </geometry>
      <material name="Blue">
        <color rgba="0.25 0.25 0.25 1.0"/>
      </material>
    </visual>
    <collision>
      <origin rpy="0 0 0 " xyz="0.0 0.0 0.0"/>
      <geometry>
        <cylinder length="0.105" radius="0.04"/>
      </geometry>
    </collision>
  </link>
  <gazebo reference="shoulder_link1_left">
    <material>Gazebo/Blue</material>
    <turnGravityOff>false</turnGravityOff>
  </gazebo>
  <link name="shoulder_link2_left">
    <inertial>
      <origin rpy="0 0 0" xyz="0.0 0.0 0.0"/>
      <mass value="0.1"/>
      <inertia ixx="0.001" ixy="0" ixz="0" iyy="0.001" iyz="0" izz="0.001"/>
    </inertial>
    <visual>
      <origin rpy="0 0 0" xyz="0.0 0.0 0.0"/>
      <geometry>
        <cylinder length="0.01" radius="0.01"/>
      </geometry>
      <material name="Red">
        <color rgba="0 0 1 1.0"/>
      </material>
    </visual>
    <collision>
      <origin rpy="0 0 0" xyz="0.0 0.0 0.0"/>
      <geometry>
        <cylinder length="0.01" radius="0.01"/>
      </geometry>
    </collision>
  </link>
  <gazebo reference="shoulder_link2_left">
    <material>Gazebo/Red</material>
    <turnGravityOff>false</turnGravityOff>
  </gazebo>
  <link name="upper_arm_left">
    <inertial>
      <origin rpy="0 0 0" xyz="0.0 -0.16 0.0"/>
      <mass value="2.9"/>
      <inertia ixx="0.027" ixy="0" ixz="0" iyy="0.027" iyz="0" izz="0.004"/>
    </inertial>
    <visual>
      <origin rpy="1.5708 0 0" xyz="0.0 -0.16 0.0"/>
      <geometry>
        <cylinder length="0.32" radius="0.0525"/>
      </geometry>
      <material name="Grey">
        <color rgba="0.65 0.65 0.65 1.0"/>
      </material>
    </visual>
    <collision>
      <origin rpy="1.5708 0 0" xyz="0.0 -0.16 0.0"/>
      <geometry>
        <cylinder length="0.32" radius="0.0525"/>
      </geometry>
    </collision>
  </link>
  <gazebo reference="upper_arm_left">
    <material>Gazebo/Grey</material>
    <turnGravityOff>false</turnGravityOff>
  </gazebo>
  <link name="elbow_link4_left">
    <inertial>
      <origin rpy="0 0 0" xyz="0.0 0.0 0.0"/>
      <mass value="0.1"/>
      <inertia ixx="0.001" ixy="0" ixz="0" iyy="0.001" iyz="0" izz="0.001"/>
    </inertial>
    <visual>
      <origin rpy="1.5708 0 0" xyz="0.0 0.0 0.0"/>
      <geometry>
        <cylinder length="0.10" radius="0.03"/>
      </geometry>
      <material name="Blue">
        <color rgba="0.25 0.25 0.25 1.0"/>
      </material>
    </visual>
    <collision>
      <origin rpy="1.5708 0 0" xyz="0.0 0.0 0.0"/>
      <geometry>
        <cylinder length="0.10" radius="0.03"/>
      </geometry>
    </collision>
  </link>
  <gazebo reference="elbow_link4_left">
    <material>Gazebo/Blue</material>
    <turnGravityOff>false</turnGravityOff>
  </gazebo>
  <link name="fore_arm_left">
    <inertial>
      <origin rpy="0.0 0 0" xyz="0.0 -0.14 0.0"/>
      <mass value="0.8"/>
      <inertia ixx="0.0054" ixy="0" ixz="0" iyy="0.0054" iyz="0" izz="0.0004"/>
    </inertial>
    <visual>
      <origin rpy="1.5708 0 0" xyz="0.0 -0.14 0.0"/>
      <geometry>
        <box size="0.065 0.065 0.28"/>
      </geometry>
      <material name="Grey">
        <color rgba="0.65 0.65 0.65 1.0"/>
      </material>
    </visual>
    <collision>
      <origin rpy="1.5708 0 0" xyz="0.0 -0.14 0.0"/>
      <geometry>
        <box size="0.065 0.065 0.28"/>
      </geometry>
    </collision>
  </link>
  <gazebo reference="fore_arm_left">
    <material>Gazebo/Grey</material>
    <turnGravityOff>false</turnGravityOff>
  </gazebo>
  <link name="wrist_link6_left">
    <inertial>
      <origin rpy="0 0 0" xyz="0.0 0.0 0.0"/>
      <mass value="0.01"/>
      <inertia ixx="0.001" ixy="0" ixz="0" iyy="0.001" iyz="0" izz="0.001"/>
    </inertial>
    <visual>
      <origin rpy="1.5708 0 0" xyz="0.0 0.0 0.0"/>
      <geometry>
        <cylinder length="0.09" radius="0.02"/>
      </geometry>
      <material name="Blue">
        <color rgba="0.25 0.25 0.25 1.0"/>
      </material>
    </visual>
    <collision>
      <origin rpy="1.5708 0 0" xyz="0.0 0.0 0.0"/>
      <geometry>
        <cylinder length="0.09" radius="0.02"/>
      </geometry>
    </collision>
  </link>
  <gazebo reference="wrist_link6_left">
    <material>Gazebo/Blue</material>
    <turnGravityOff>false</turnGravityOff>
  </gazebo>
  <link name="hand_left">
    <inertial>
      <origin rpy="0 0 0" xyz="0.0425 0.0 0.0"/>
      <mass value="0.2"/>
      <inertia ixx="0.01" ixy="0" ixz="0" iyy="0.01" iyz="0" izz="0.01"/>
    </inertial>
    <visual>
      <origin rpy="0 0 0" xyz="0.0425 0.0 0.0"/>
      <geometry>
        <box size="0.080 0.085 0.038"/>
      </geometry>
      <material name="Red">
        <color rgba="0 0 1 1.0"/>
      </material>
    </visual>
    <collision>
      <origin rpy="0 0 0" xyz="0.0425 0.0 0.0"/>
      <geometry>
        <box size="0.080 0.085 0.038"/>
      </geometry>
    </collision>
  </link>
  <gazebo reference="hand_left">
    <material>Gazebo/Red</material>
    <turnGravityOff>false</turnGravityOff>
  </gazebo>
  <link name="finger1_left">
    <inertial>
      <origin rpy="0 0 0" xyz="0.0 0.0 -0.055"/>
      <mass value="0.05"/>
      <inertia ixx="0.00037" ixy="0" ixz="0" iyy="0.00052" iyz="0" izz="0.00052"/>
    </inertial>
    <visual>
      <origin rpy="0 0 0" xyz="0.0 0.0 -0.055"/>
      <geometry>
        <box size="0.02 0.022 0.11"/>
      </geometry>
      <material name="Black">
        <color rgba="0.15 0.15 0.15 1.0"/>
      </material>
    </visual>
    <collision>
      <origin rpy="0 0 0" xyz="0.0 0.0 -0.055"/>
      <geometry>
        <box size="0.02 0.022 0.11"/>
      </geometry>
    </collision>
  </link>
  <gazebo reference="finger1_left">
    <material>Gazebo/Black</material>
    <turnGravityOff>false</turnGravityOff>
  </gazebo>
  <link name="finger2_left">
    <inertial>
      <origin rpy="0 0 0" xyz="0.0 0.0 -0.055"/>
      <mass value="0.05"/>
      <inertia ixx="0.00037" ixy="0" ixz="0" iyy="0.00052" iyz="0" izz="0.00052"/>
    </inertial>
    <visual>
      <origin rpy="0 0 0" xyz="0.0 0.0 -0.055"/>
      <geometry>
        <box size="0.02 0.022 0.11"/>
      </geometry>
      <material name="Black">
        <color rgba="0.15 0.15 0.15 1.0"/>
      </material>
    </visual>
    <collision>
      <origin rpy="0 0 0" xyz="0.0 0.0 -0.055"/>
      <geometry>
        <box size="0.02 0.022 0.11"/>
      </geometry>
    </collision>
  </link>
  <gazebo reference="finger2_left">
    <material>Gazebo/Black</material>
    <turnGravityOff>false</turnGravityOff>
  </gazebo>
  <link name="grippoint_left">
    <inertial>
      <origin rpy="0 0 0" xyz="-0.1 0.0 0.0"/>
      <mass value="0.01"/>
      <inertia ixx="0.0001" ixy="0" ixz="0" iyy="0.0001" iyz="0" izz="0.0001"/>
    </inertial>
    <visual>
      <origin rpy="0 0 0 " xyz="-0.1 0.0 0.0"/>
      <geometry>
        <box size="0.01 0.01 0.01"/>
      </geometry>
      <material name="Blue">
        <color rgba="0.25 0.25 0.25 1.0"/>
      </material>
    </visual>
    <collision>
      <origin rpy="0 0 0 " xyz="-0.1 0.0 0.0"/>
      <geometry>
        <box size="0.01 0.01 0.01"/>
      </geometry>
    </collision>
  </link>
  <gazebo reference="grippoint_left">
    <material>Gazebo/Blue</material>
    <turnGravityOff>false</turnGravityOff>
  </gazebo>
  <joint name="shoulder_yaw_joint_left" type="revolute">
    <parent link="torso"/>
    <child link="shoulder_link1_left"/>
    <origin rpy="1.5708 0 0" xyz="0.05 -0.202  0.0"/>
    <axis xyz="0 -1 0"/>
    <dynamics damping="6.0" friction="4.87"/>
    <limit effort="13.4" lower="-1.5708" upper="0.0" velocity="1.0"/>
  </joint>
  <joint name="shoulder_pitch_joint_left" type="revolute">
    <parent link="shoulder_link1_left"/>
    <child link="shoulder_link2_left"/>
    <origin rpy="-1.5708  0 0" xyz="0.0 0.0 0.0"/>
    <axis xyz="0 -1 0"/>
    <dynamics damping="6.0" friction="6.06"/>
    <limit effort="13.4" lower="-3.1415" upper="0" velocity="1.0"/>
  </joint>
  <joint name="shoulder_roll_joint_left" type="revolute">
    <parent link="shoulder_link2_left"/>
    <child link="upper_arm_left"/>
    <origin rpy="1.5708 0 3.1416" xyz="0.0 0.0 0.0"/>
    <axis xyz="0 1 0"/>
    <dynamics damping="6.0" friction="2.16"/>
    <limit effort="9.8" lower="-1.5708" upper="1.5708" velocity="1.0"/>
  </joint>
  <joint name="elbow_pitch_joint_left" type="revolute">
    <parent link="upper_arm_left"/>
    <child link="elbow_link4_left"/>
    <origin rpy="-1.5708 0 0" xyz="0.01 -0.32 0.0"/>
    <axis xyz="0 -1 0"/>
    <dynamics damping="2.5" friction="1.18"/>
    <limit effort="4.5" lower="0.0" upper="1.90" velocity="1.0"/>
  </joint>
  <joint name="elbow_roll_joint_left" type="revolute">
    <parent link="elbow_link4_left"/>
    <child link="fore_arm_left"/>
    <origin rpy="1.5708 0 0" xyz="0.0 0.0 0.0"/>
    <axis xyz="0 1 0"/>
    <dynamics damping="2.5" friction="1.35"/>
    <limit effort="4.5" lower="-1.81" upper="1.81" velocity="1.0"/>
  </joint>
  <joint name="wrist_pitch_joint_left" type="revolute">
    <parent link="fore_arm_left"/>
    <child link="wrist_link6_left"/>
    <origin rpy="-1.5708 0 0" xyz="0.01 -0.28 0.0"/>
    <axis xyz="0 -1 0"/>
    <dynamics damping="0.5" friction="0.63"/>
    <limit effort="1" lower="-2.52" upper="-0.62" velocity="1.0"/>
  </joint>
  <joint name="wrist_yaw_joint_left" type="revolute">
    <parent link="wrist_link6_left"/>
    <child link="hand_left"/>
    <origin rpy="0 0 0" xyz="0.0 0.0 0.0"/>
    <axis xyz="0 0 1"/>
    <dynamics damping="0.5" friction="0.68"/>
    <limit effort="1" lower="-0.70" upper="0.70" velocity="1.0"/>
  </joint>
  <joint name="finger1_joint_left" type="revolute">
    <parent link="hand_left"/>
    <child link="finger1_left"/>
    <origin rpy="0 -1.57 0" xyz=" 0.075 0.04 0"/>
    <axis xyz="1 0 0"/>
    <dynamics damping="0.1" friction="0.63"/>
    <limit effort="3" lower="-0.7854" upper="0.7854" velocity="1.0"/>
  </joint>
  <joint name="finger2_joint_left" type="revolute">
    <parent link="hand_left"/>
    <child link="finger2_left"/>
    <origin rpy="0 -1.57 0" xyz="0.075 -0.04 0"/>
    <axis xyz="1 0 0"/>
    <dynamics damping="0.1" friction="0.0"/>
    <limit effort="3" lower="-0.7854" upper="0.7854" velocity="1.0"/>
  </joint>
  <joint name="grippoint_joint_left" type="fixed">
    <parent link="hand_left"/>
    <child link="grippoint_left"/>
    <axis xyz="0  0 1"/>
    <origin rpy="  0.0 0.0 0.0" xyz="0.14 0.0 0.0"/>
  </joint>
  <link name="shoulder_link1_right">
    <inertial>
      <origin rpy="0 0 0" xyz="0.0 0.0 0.0"/>
      <mass value="0.1"/>
      <inertia ixx="0.01" ixy="0" ixz="0" iyy="0.01" iyz="0" izz="0.01"/>
    </inertial>
    <visual>
      <origin rpy="0 0 0 " xyz="0.0 0.0 0.0"/>
      <geometry>
        <cylinder length="0.105" radius="0.04"/>
      </geometry>
      <material name="Blue">
        <color rgba="0.25 0.25 0.25 1.0"/>
      </material>
    </visual>
    <collision>
      <origin rpy="0 0 0 " xyz="0.0 0.0 0.0"/>
      <geometry>
        <cylinder length="0.105" radius="0.04"/>
      </geometry>
    </collision>
  </link>
  <gazebo reference="shoulder_link1_right">
    <material>Gazebo/Blue</material>
    <turnGravityOff>false</turnGravityOff>
  </gazebo>
  <link name="shoulder_link2_right">
    <inertial>
      <origin rpy="0 0 0" xyz="0.0 0.0 0.0"/>
      <mass value="0.1"/>
      <inertia ixx="0.001" ixy="0" ixz="0" iyy="0.001" iyz="0" izz="0.001"/>
    </inertial>
    <visual>
      <origin rpy="0 0 0" xyz="0.0 0.0 0.0"/>
      <geometry>
        <cylinder length="0.01" radius="0.01"/>
      </geometry>
      <material name="Red">
        <color rgba="0 0 1 1.0"/>
      </material>
    </visual>
    <collision>
      <origin rpy="0 0 0" xyz="0.0 0.0 0.0"/>
      <geometry>
        <cylinder length="0.01" radius="0.01"/>
      </geometry>
    </collision>
  </link>
  <gazebo reference="shoulder_link2_right">
    <material>Gazebo/Red</material>
    <turnGravityOff>false</turnGravityOff>
  </gazebo>
  <link name="upper_arm_right">
    <inertial>
      <origin rpy="0 0 0" xyz="0.0 -0.16 0.0"/>
      <mass value="2.9"/>
      <inertia ixx="0.027" ixy="0" ixz="0" iyy="0.027" iyz="0" izz="0.004"/>
    </inertial>
    <visual>
      <origin rpy="1.5708 0 0" xyz="0.0 -0.16 0.0"/>
      <geometry>
        <cylinder length="0.32" radius="0.0525"/>
      </geometry>
      <material name="Grey">
        <color rgba="0.65 0.65 0.65 1.0"/>
      </material>
    </visual>
    <collision>
      <origin rpy="1.5708 0 0" xyz="0.0 -0.16 0.0"/>
      <geometry>
        <cylinder length="0.32" radius="0.0525"/>
      </geometry>
    </collision>
  </link>
  <gazebo reference="upper_arm_right">
    <material>Gazebo/Grey</material>
    <turnGravityOff>false</turnGravityOff>
  </gazebo>
  <link name="elbow_link4_right">
    <inertial>
      <origin rpy="0 0 0" xyz="0.0 0.0 0.0"/>
      <mass value="0.1"/>
      <inertia ixx="0.001" ixy="0" ixz="0" iyy="0.001" iyz="0" izz="0.001"/>
    </inertial>
    <visual>
      <origin rpy="1.5708 0 0" xyz="0.0 0.0 0.0"/>
      <geometry>
        <cylinder length="0.10" radius="0.03"/>
      </geometry>
      <material name="Blue">
        <color rgba="0.25 0.25 0.25 1.0"/>
      </material>
    </visual>
    <collision>
      <origin rpy="1.5708 0 0" xyz="0.0 0.0 0.0"/>
      <geometry>
        <cylinder length="0.10" radius="0.03"/>
      </geometry>
    </collision>
  </link>
  <gazebo reference="elbow_link4_right">
    <material>Gazebo/Blue</material>
    <turnGravityOff>false</turnGravityOff>
  </gazebo>
  <link name="fore_arm_right">
    <inertial>
      <origin rpy="0.0 0 0" xyz="0.0 -0.14 0.0"/>
      <mass value="0.8"/>
      <inertia ixx="0.0054" ixy="0" ixz="0" iyy="0.0054" iyz="0" izz="0.0004"/>
    </inertial>
    <visual>
      <origin rpy="1.5708 0 0" xyz="0.0 -0.14 0.0"/>
      <geometry>
        <box size="0.065 0.065 0.28"/>
      </geometry>
      <material name="Grey">
        <color rgba="0.65 0.65 0.65 1.0"/>
      </material>
    </visual>
    <collision>
      <origin rpy="1.5708 0 0" xyz="0.0 -0.14 0.0"/>
      <geometry>
        <box size="0.065 0.065 0.28"/>
      </geometry>
    </collision>
  </link>
  <gazebo reference="fore_arm_right">
    <material>Gazebo/Grey</material>
    <turnGravityOff>false</turnGravityOff>
  </gazebo>
  <link name="wrist_link6_right">
    <inertial>
      <origin rpy="0 0 0" xyz="0.0 0.0 0.0"/>
      <mass value="0.01"/>
      <inertia ixx="0.001" ixy="0" ixz="0" iyy="0.001" iyz="0" izz="0.001"/>
    </inertial>
    <visual>
      <origin rpy="1.5708 0 0" xyz="0.0 0.0 0.0"/>
      <geometry>
        <cylinder length="0.09" radius="0.02"/>
      </geometry>
      <material name="Blue">
        <color rgba="0.25 0.25 0.25 1.0"/>
      </material>
    </visual>
    <collision>
      <origin rpy="1.5708 0 0" xyz="0.0 0.0 0.0"/>
      <geometry>
        <cylinder length="0.09" radius="0.02"/>
      </geometry>
    </collision>
  </link>
  <gazebo reference="wrist_link6_right">
    <material>Gazebo/Blue</material>
    <turnGravityOff>false</turnGravityOff>
  </gazebo>
  <link name="hand_right">
    <inertial>
      <origin rpy="0 0 0" xyz="0.0425 0.0 0.0"/>
      <mass value="0.2"/>
      <inertia ixx="0.01" ixy="0" ixz="0" iyy="0.01" iyz="0" izz="0.01"/>
    </inertial>
    <visual>
      <origin rpy="0 0 0" xyz="0.0425 0.0 0.0"/>
      <geometry>
        <box size="0.080 0.085 0.038"/>
      </geometry>
      <material name="Red">
        <color rgba="0 0 1 1.0"/>
      </material>
    </visual>
    <collision>
      <origin rpy="0 0 0" xyz="0.0425 0.0 0.0"/>
      <geometry>
        <box size="0.080 0.085 0.038"/>
      </geometry>
    </collision>
  </link>
  <gazebo reference="hand_right">
    <material>Gazebo/Red</material>
    <turnGravityOff>false</turnGravityOff>
  </gazebo>
  <link name="finger1_right">
    <inertial>
      <origin rpy="0 0 0" xyz="0.0 0.0 -0.055"/>
      <mass value="0.05"/>
      <inertia ixx="0.00037" ixy="0" ixz="0" iyy="0.00052" iyz="0" izz="0.00052"/>
    </inertial>
    <visual>
      <origin rpy="0 0 0" xyz="0.0 0.0 -0.055"/>
      <geometry>
        <box size="0.02 0.022 0.11"/>
      </geometry>
      <material name="Black">
        <color rgba="0.15 0.15 0.15 1.0"/>
      </material>
    </visual>
    <collision>
      <origin rpy="0 0 0" xyz="0.0 0.0 -0.055"/>
      <geometry>
        <box size="0.02 0.022 0.11"/>
      </geometry>
    </collision>
  </link>
  <gazebo reference="finger1_right">
    <material>Gazebo/Black</material>
    <turnGravityOff>false</turnGravityOff>
  </gazebo>
  <link name="finger2_right">
    <inertial>
      <origin rpy="0 0 0" xyz="0.0 0.0 -0.055"/>
      <mass value="0.05"/>
      <inertia ixx="0.00037" ixy="0" ixz="0" iyy="0.00052" iyz="0" izz="0.00052"/>
    </inertial>
    <visual>
      <origin rpy="0 0 0" xyz="0.0 0.0 -0.055"/>
      <geometry>
        <box size="0.02 0.022 0.11"/>
      </geometry>
      <material name="Black">
        <color rgba="0.15 0.15 0.15 1.0"/>
      </material>
    </visual>
    <collision>
      <origin rpy="0 0 0" xyz="0.0 0.0 -0.055"/>
      <geometry>
        <box size="0.02 0.022 0.11"/>
      </geometry>
    </collision>
  </link>
  <gazebo reference="finger2_right">
    <material>Gazebo/Black</material>
    <turnGravityOff>false</turnGravityOff>
  </gazebo>
  <link name="grippoint_right">
    <inertial>
      <origin rpy="0 0 0" xyz="-0.1 0.0 0.0"/>
      <mass value="0.01"/>
      <inertia ixx="0.0001" ixy="0" ixz="0" iyy="0.0001" iyz="0" izz="0.0001"/>
    </inertial>
    <visual>
      <origin rpy="0 0 0 " xyz="-0.1 0.0 0.0"/>
      <geometry>
        <box size="0.01 0.01 0.01"/>
      </geometry>
      <material name="Blue">
        <color rgba="0.25 0.25 0.25 1.0"/>
      </material>
    </visual>
    <collision>
      <origin rpy="0 0 0 " xyz="-0.1 0.0 0.0"/>
      <geometry>
        <box size="0.01 0.01 0.01"/>
      </geometry>
    </collision>
  </link>
  <gazebo reference="grippoint_right">
    <material>Gazebo/Blue</material>
    <turnGravityOff>false</turnGravityOff>
  </gazebo>
  <joint name="shoulder_yaw_joint_right" type="revolute">
    <parent link="torso"/>
    <child link="shoulder_link1_right"/>
    <origin rpy="-1.5708 0 0" xyz="0.05 +0.202  0.0"/>
    <axis xyz="0 -1 0"/>
    <dynamics damping="6.0" friction="4.87"/>
    <limit effort="13.4" lower="-1.5708" upper="0.0" velocity="1.0"/>
  </joint>
  <joint name="shoulder_pitch_joint_right" type="revolute">
    <parent link="shoulder_link1_right"/>
    <child link="shoulder_link2_right"/>
    <origin rpy="-1.5708  0 0" xyz="0.0 0.0 0.0"/>
    <axis xyz="0 -1 0"/>
    <dynamics damping="6.0" friction="6.06"/>
    <limit effort="13.4" lower="-3.1415" upper="0" velocity="1.0"/>
  </joint>
  <joint name="shoulder_roll_joint_right" type="revolute">
    <parent link="shoulder_link2_right"/>
    <child link="upper_arm_right"/>
    <origin rpy="1.5708 0 0.0" xyz="0.0 0.0 0.0"/>
    <axis xyz="0 1 0"/>
    <dynamics damping="6.0" friction="2.16"/>
    <limit effort="9.8" lower="-1.5708" upper="1.5708" velocity="1.0"/>
  </joint>
  <joint name="elbow_pitch_joint_right" type="revolute">
    <parent link="upper_arm_right"/>
    <child link="elbow_link4_right"/>
    <origin rpy="-1.5708 0 0" xyz="0.01 -0.32 0.0"/>
    <axis xyz="0 -1 0"/>
    <dynamics damping="2.5" friction="1.18"/>
    <limit effort="4.5" lower="0.0" upper="1.90" velocity="1.0"/>
  </joint>
  <joint name="elbow_roll_joint_right" type="revolute">
    <parent link="elbow_link4_right"/>
    <child link="fore_arm_right"/>
    <origin rpy="1.5708 0 0" xyz="0.0 0.0 0.0"/>
    <axis xyz="0 1 0"/>
    <dynamics damping="2.5" friction="1.35"/>
    <limit effort="4.5" lower="-1.81" upper="1.81" velocity="1.0"/>
  </joint>
  <joint name="wrist_pitch_joint_right" type="revolute">
    <parent link="fore_arm_right"/>
    <child link="wrist_link6_right"/>
    <origin rpy="-1.5708 0 0" xyz="0.01 -0.28 0.0"/>
    <axis xyz="0 -1 0"/>
    <dynamics damping="0.5" friction="0.63"/>
    <limit effort="1" lower="-2.52" upper="-0.62" velocity="1.0"/>
  </joint>
  <joint name="wrist_yaw_joint_right" type="revolute">
    <parent link="wrist_link6_right"/>
    <child link="hand_right"/>
    <origin rpy="0 0 0" xyz="0.0 0.0 0.0"/>
    <axis xyz="0 0 1"/>
    <dynamics damping="0.5" friction="0.68"/>
    <limit effort="1" lower="-0.70" upper="0.70" velocity="1.0"/>
  </joint>
  <joint name="finger1_joint_right" type="revolute">
    <parent link="hand_right"/>
    <child link="finger1_right"/>
    <origin rpy="0 -1.57 0" xyz=" 0.075 0.04 0"/>
    <axis xyz="1 0 0"/>
    <dynamics damping="0.1" friction="0.63"/>
    <limit effort="3" lower="-0.7854" upper="0.7854" velocity="1.0"/>
  </joint>
  <joint name="finger2_joint_right" type="revolute">
    <parent link="hand_right"/>
    <child link="finger2_right"/>
    <origin rpy="0 -1.57 0" xyz="0.075 -0.04 0"/>
    <axis xyz="1 0 0"/>
    <dynamics damping="0.1" friction="0.0"/>
    <limit effort="3" lower="-0.7854" upper="0.7854" velocity="1.0"/>
  </joint>
  <joint name="grippoint_joint_right" type="fixed">
    <parent link="hand_right"/>
    <child link="grippoint_right"/>
    <axis xyz="0  0 1"/>
    <origin rpy="  0.0 0.0 0.0" xyz="0.14 0.0 0.0"/>
  </joint>
  <!--====BUILD TRANSMISSION ELEMENTS====-->
  <transmission name="spindle_trans" type="pr2_mechanism_model/SimpleTransmission">
    <actuator name="spindle_motor"/>
    <joint name="spindle_joint"/>
    <mechanicalReduction>1</mechanicalReduction>
    <motorTorqueConstant>1</motorTorqueConstant>
  </transmission>
  <transmission name="shoulder_yaw_trans_left" type="pr2_mechanism_model/SimpleTransmission">
    <actuator name="shoulder_yaw_motor_left"/>
    <joint name="shoulder_yaw_joint_left"/>
    <mechanicalReduction>1</mechanicalReduction>
    <motorTorqueConstant>1</motorTorqueConstant>
  </transmission>
  <transmission name="shoulder_pitch_trans_left" type="pr2_mechanism_model/SimpleTransmission">
    <actuator name="shoulder_pitch_motor_left"/>
    <joint name="shoulder_pitch_joint_left"/>
    <mechanicalReduction>1</mechanicalReduction>
    <motorTorqueConstant>1</motorTorqueConstant>
  </transmission>
  <transmission name="shoulder_roll_trans_left" type="pr2_mechanism_model/SimpleTransmission">
    <actuator name="shoulder_roll_motor_left"/>
    <joint name="shoulder_roll_joint_left"/>
    <mechanicalReduction>1</mechanicalReduction>
    <motorTorqueConstant>1</motorTorqueConstant>
  </transmission>
  <transmission name="elbow_pitch_trans_left" type="pr2_mechanism_model/SimpleTransmission">
    <actuator name="elbow_pitch_motor_left"/>
    <joint name="elbow_pitch_joint_left"/>
    <mechanicalReduction>1</mechanicalReduction>
    <motorTorqueConstant>1</motorTorqueConstant>
  </transmission>
  <transmission name="elbow_roll_trans_left" type="pr2_mechanism_model/SimpleTransmission">
    <actuator name="elbow_roll_motor_left"/>
    <joint name="elbow_roll_joint_left"/>
    <mechanicalReduction>1</mechanicalReduction>
    <motorTorqueConstant>1</motorTorqueConstant>
  </transmission>
  <transmission name="wrist_yaw_trans_left" type="pr2_mechanism_model/SimpleTransmission">
    <actuator name="wrist_yaw_motor_left"/>
    <joint name="wrist_yaw_joint_left"/>
    <mechanicalReduction>1</mechanicalReduction>
    <motorTorqueConstant>1</motorTorqueConstant>
  </transmission>
  <transmission name="wrist_pitch_trans_left" type="pr2_mechanism_model/SimpleTransmission">
    <actuator name="wrist_pitch_motor_left"/>
    <joint name="wrist_pitch_joint_left"/>
    <mechanicalReduction>1</mechanicalReduction>
    <motorTorqueConstant>1</motorTorqueConstant>
  </transmission>
  <transmission name="finger1_trans_left" type="pr2_mechanism_model/SimpleTransmission">
    <actuator name="finger1_motor_left"/>
    <joint name="finger1_joint_left"/>
    <mechanicalReduction>1</mechanicalReduction>
    <motorTorqueConstant>1</motorTorqueConstant>
  </transmission>
  <transmission name="finger2_trans_left" type="pr2_mechanism_model/SimpleTransmission">
    <actuator name="finger2_motor_left"/>
    <joint name="finger2_joint_left"/>
    <mechanicalReduction>1</mechanicalReduction>
    <motorTorqueConstant>1</motorTorqueConstant>
  </transmission>
  <transmission name="shoulder_yaw_trans_right" type="pr2_mechanism_model/SimpleTransmission">
    <actuator name="shoulder_yaw_motor_right"/>
    <joint name="shoulder_yaw_joint_right"/>
    <mechanicalReduction>1</mechanicalReduction>
    <motorTorqueConstant>1</motorTorqueConstant>
  </transmission>
  <transmission name="shoulder_pitch_trans_right" type="pr2_mechanism_model/SimpleTransmission">
    <actuator name="shoulder_pitch_motor_right"/>
    <joint name="shoulder_pitch_joint_right"/>
    <mechanicalReduction>1</mechanicalReduction>
    <motorTorqueConstant>1</motorTorqueConstant>
  </transmission>
  <transmission name="shoulder_roll_trans_right" type="pr2_mechanism_model/SimpleTransmission">
    <actuator name="shoulder_roll_motor_right"/>
    <joint name="shoulder_roll_joint_right"/>
    <mechanicalReduction>1</mechanicalReduction>
    <motorTorqueConstant>1</motorTorqueConstant>
  </transmission>
  <transmission name="elbow_pitch_trans_right" type="pr2_mechanism_model/SimpleTransmission">
    <actuator name="elbow_pitch_motor_right"/>
    <joint name="elbow_pitch_joint_right"/>
    <mechanicalReduction>1</mechanicalReduction>
    <motorTorqueConstant>1</motorTorqueConstant>
  </transmission>
  <transmission name="elbow_roll_trans_right" type="pr2_mechanism_model/SimpleTransmission">
    <actuator name="elbow_roll_motor_right"/>
    <joint name="elbow_roll_joint_right"/>
    <mechanicalReduction>1</mechanicalReduction>
    <motorTorqueConstant>1</motorTorqueConstant>
  </transmission>
  <transmission name="wrist_yaw_trans_right" type="pr2_mechanism_model/SimpleTransmission">
    <actuator name="wrist_yaw_motor_right"/>
    <joint name="wrist_yaw_joint_right"/>
    <mechanicalReduction>1</mechanicalReduction>
    <motorTorqueConstant>1</motorTorqueConstant>
  </transmission>
  <transmission name="wrist_pitch_trans_right" type="pr2_mechanism_model/SimpleTransmission">
    <actuator name="wrist_pitch_motor_right"/>
    <joint name="wrist_pitch_joint_right"/>
    <mechanicalReduction>1</mechanicalReduction>
    <motorTorqueConstant>1</motorTorqueConstant>
  </transmission>
  <transmission name="finger1_trans_right" type="pr2_mechanism_model/SimpleTransmission">
    <actuator name="finger1_motor_right"/>
    <joint name="finger1_joint_right"/>
    <mechanicalReduction>1</mechanicalReduction>
    <motorTorqueConstant>1</motorTorqueConstant>
  </transmission>
  <transmission name="finger2_trans_right" type="pr2_mechanism_model/SimpleTransmission">
    <actuator name="finger2_motor_right"/>
    <joint name="finger2_joint_right"/>
    <mechanicalReduction>1</mechanicalReduction>
    <motorTorqueConstant>1</motorTorqueConstant>
  </transmission>
  <transmission name="wheel_inner_trans_left_front" type="pr2_mechanism_model/SimpleTransmission">
    <actuator name="wheel_inner_motor_left_front"/>
    <joint name="wheel_inner_joint_left_front"/>
    <mechanicalReduction>1</mechanicalReduction>
    <motorTorqueConstant>1</motorTorqueConstant>
  </transmission>
  <transmission name="wheel_inner_trans_right_front" type="pr2_mechanism_model/SimpleTransmission">
    <actuator name="wheel_inner_motor_right_front"/>
    <joint name="wheel_inner_joint_right_front"/>
    <mechanicalReduction>1</mechanicalReduction>
    <motorTorqueConstant>1</motorTorqueConstant>
  </transmission>
  <transmission name="wheel_inner_trans_left_rear" type="pr2_mechanism_model/SimpleTransmission">
    <actuator name="wheel_inner_motor_left_rear"/>
    <joint name="wheel_inner_joint_left_rear"/>
    <mechanicalReduction>1</mechanicalReduction>
    <motorTorqueConstant>1</motorTorqueConstant>
  </transmission>
  <transmission name="wheel_inner_trans_right_rear" type="pr2_mechanism_model/SimpleTransmission">
    <actuator name="wheel_inner_motor_right_rear"/>
    <joint name="wheel_inner_joint_right_rear"/>
    <mechanicalReduction>1</mechanicalReduction>
    <motorTorqueConstant>1</motorTorqueConstant>
  </transmission>
  <transmission name="omniwheel_trans_left_front" type="pr2_mechanism_model/SimpleTransmission">
    <actuator name="omniwheel_motor_left_front"/>
    <joint name="omni_sphere1_joint_left_front"/>
    <mechanicalReduction>1</mechanicalReduction>
    <motorTorqueConstant>1</motorTorqueConstant>
  </transmission>
  <transmission name="omniwheel_trans_right_front" type="pr2_mechanism_model/SimpleTransmission">
    <actuator name="omniwheel_motor_right_front"/>
    <joint name="omni_sphere1_joint_right_front"/>
    <mechanicalReduction>1</mechanicalReduction>
    <motorTorqueConstant>1</motorTorqueConstant>
  </transmission>
  <transmission name="omniwheel_trans_left_rear" type="pr2_mechanism_model/SimpleTransmission">
    <actuator name="omniwheel_motor_left_rear"/>
    <joint name="omni_sphere1_joint_left_rear"/>
    <mechanicalReduction>1</mechanicalReduction>
    <motorTorqueConstant>1</motorTorqueConstant>
  </transmission>
  <transmission name="omniwheel_trans_right_rear" type="pr2_mechanism_model/SimpleTransmission">
    <actuator name="omniwheel_motor_right_rear"/>
    <joint name="omni_sphere1_joint_right_rear"/>
    <mechanicalReduction>1</mechanicalReduction>
    <motorTorqueConstant>1</motorTorqueConstant>
  </transmission>
  <transmission name="omniwheel_trans_left_front" type="pr2_mechanism_model/SimpleTransmission">
    <actuator name="omniwheel_motor_left_front"/>
    <joint name="omni_sphere2_joint_left_front"/>
    <mechanicalReduction>1</mechanicalReduction>
    <motorTorqueConstant>1</motorTorqueConstant>
  </transmission>
  <transmission name="omniwheel_trans_right_front" type="pr2_mechanism_model/SimpleTransmission">
    <actuator name="omniwheel_motor_right_front"/>
    <joint name="omni_sphere2_joint_right_front"/>
    <mechanicalReduction>1</mechanicalReduction>
    <motorTorqueConstant>1</motorTorqueConstant>
  </transmission>
  <transmission name="omniwheel_trans_left_rear" type="pr2_mechanism_model/SimpleTransmission">
    <actuator name="omniwheel_motor_left_rear"/>
    <joint name="omni_sphere2_joint_left_rear"/>
    <mechanicalReduction>1</mechanicalReduction>
    <motorTorqueConstant>1</motorTorqueConstant>
  </transmission>
  <transmission name="omniwheel_trans_right_rear" type="pr2_mechanism_model/SimpleTransmission">
    <actuator name="omniwheel_motor_right_rear"/>
    <joint name="omni_sphere2_joint_right_rear"/>
    <mechanicalReduction>1</mechanicalReduction>
    <motorTorqueConstant>1</motorTorqueConstant>
  </transmission>
  <transmission name="omniwheel_trans_left_front" type="pr2_mechanism_model/SimpleTransmission">
    <actuator name="omniwheel_motor_left_front"/>
    <joint name="omni_sphere3_joint_left_front"/>
    <mechanicalReduction>1</mechanicalReduction>
    <motorTorqueConstant>1</motorTorqueConstant>
  </transmission>
  <transmission name="omniwheel_trans_right_front" type="pr2_mechanism_model/SimpleTransmission">
    <actuator name="omniwheel_motor_right_front"/>
    <joint name="omni_sphere3_joint_right_front"/>
    <mechanicalReduction>1</mechanicalReduction>
    <motorTorqueConstant>1</motorTorqueConstant>
  </transmission>
  <transmission name="omniwheel_trans_left_rear" type="pr2_mechanism_model/SimpleTransmission">
    <actuator name="omniwheel_motor_left_rear"/>
    <joint name="omni_sphere3_joint_left_rear"/>
    <mechanicalReduction>1</mechanicalReduction>
    <motorTorqueConstant>1</motorTorqueConstant>
  </transmission>
  <transmission name="omniwheel_trans_right_rear" type="pr2_mechanism_model/SimpleTransmission">
    <actuator name="omniwheel_motor_right_rear"/>
    <joint name="omni_sphere3_joint_right_rear"/>
    <mechanicalReduction>1</mechanicalReduction>
    <motorTorqueConstant>1</motorTorqueConstant>
  </transmission>
  <transmission name="omniwheel_trans_left_front" type="pr2_mechanism_model/SimpleTransmission">
    <actuator name="omniwheel_motor_left_front"/>
    <joint name="omni_sphere4_joint_left_front"/>
    <mechanicalReduction>1</mechanicalReduction>
    <motorTorqueConstant>1</motorTorqueConstant>
  </transmission>
  <transmission name="omniwheel_trans_right_front" type="pr2_mechanism_model/SimpleTransmission">
    <actuator name="omniwheel_motor_right_front"/>
    <joint name="omni_sphere4_joint_right_front"/>
    <mechanicalReduction>1</mechanicalReduction>
    <motorTorqueConstant>1</motorTorqueConstant>
  </transmission>
  <transmission name="omniwheel_trans_left_rear" type="pr2_mechanism_model/SimpleTransmission">
    <actuator name="omniwheel_motor_left_rear"/>
    <joint name="omni_sphere4_joint_left_rear"/>
    <mechanicalReduction>1</mechanicalReduction>
    <motorTorqueConstant>1</motorTorqueConstant>
  </transmission>
  <transmission name="omniwheel_trans_right_rear" type="pr2_mechanism_model/SimpleTransmission">
    <actuator name="omniwheel_motor_right_rear"/>
    <joint name="omni_sphere4_joint_right_rear"/>
    <mechanicalReduction>1</mechanicalReduction>
    <motorTorqueConstant>1</motorTorqueConstant>
  </transmission>
  <transmission name="omniwheel_trans_left_front" type="pr2_mechanism_model/SimpleTransmission">
    <actuator name="omniwheel_motor_left_front"/>
    <joint name="omni_sphere5_joint_left_front"/>
    <mechanicalReduction>1</mechanicalReduction>
    <motorTorqueConstant>1</motorTorqueConstant>
  </transmission>
  <transmission name="omniwheel_trans_right_front" type="pr2_mechanism_model/SimpleTransmission">
    <actuator name="omniwheel_motor_right_front"/>
    <joint name="omni_sphere5_joint_right_front"/>
    <mechanicalReduction>1</mechanicalReduction>
    <motorTorqueConstant>1</motorTorqueConstant>
  </transmission>
  <transmission name="omniwheel_trans_left_rear" type="pr2_mechanism_model/SimpleTransmission">
    <actuator name="omniwheel_motor_left_rear"/>
    <joint name="omni_sphere5_joint_left_rear"/>
    <mechanicalReduction>1</mechanicalReduction>
    <motorTorqueConstant>1</motorTorqueConstant>
  </transmission>
  <transmission name="omniwheel_trans_right_rear" type="pr2_mechanism_model/SimpleTransmission">
    <actuator name="omniwheel_motor_right_rear"/>
    <joint name="omni_sphere5_joint_right_rear"/>
    <mechanicalReduction>1</mechanicalReduction>
    <motorTorqueConstant>1</motorTorqueConstant>
  </transmission>
  <transmission name="omniwheel_trans_left_front" type="pr2_mechanism_model/SimpleTransmission">
    <actuator name="omniwheel_motor_left_front"/>
    <joint name="omni_sphere6_joint_left_front"/>
    <mechanicalReduction>1</mechanicalReduction>
    <motorTorqueConstant>1</motorTorqueConstant>
  </transmission>
  <transmission name="omniwheel_trans_right_front" type="pr2_mechanism_model/SimpleTransmission">
    <actuator name="omniwheel_motor_right_front"/>
    <joint name="omni_sphere6_joint_right_front"/>
    <mechanicalReduction>1</mechanicalReduction>
    <motorTorqueConstant>1</motorTorqueConstant>
  </transmission>
  <transmission name="omniwheel_trans_left_rear" type="pr2_mechanism_model/SimpleTransmission">
    <actuator name="omniwheel_motor_left_rear"/>
    <joint name="omni_sphere6_joint_left_rear"/>
    <mechanicalReduction>1</mechanicalReduction>
    <motorTorqueConstant>1</motorTorqueConstant>
  </transmission>
  <transmission name="omniwheel_trans_right_rear" type="pr2_mechanism_model/SimpleTransmission">
    <actuator name="omniwheel_motor_right_rear"/>
    <joint name="omni_sphere6_joint_right_rear"/>
    <mechanicalReduction>1</mechanicalReduction>
    <motorTorqueConstant>1</motorTorqueConstant>
  </transmission>
  <transmission name="omniwheel_trans_left_front" type="pr2_mechanism_model/SimpleTransmission">
    <actuator name="omniwheel_motor_left_front"/>
    <joint name="omni_sphere7_joint_left_front"/>
    <mechanicalReduction>1</mechanicalReduction>
    <motorTorqueConstant>1</motorTorqueConstant>
  </transmission>
  <transmission name="omniwheel_trans_right_front" type="pr2_mechanism_model/SimpleTransmission">
    <actuator name="omniwheel_motor_right_front"/>
    <joint name="omni_sphere7_joint_right_front"/>
    <mechanicalReduction>1</mechanicalReduction>
    <motorTorqueConstant>1</motorTorqueConstant>
  </transmission>
  <transmission name="omniwheel_trans_left_rear" type="pr2_mechanism_model/SimpleTransmission">
    <actuator name="omniwheel_motor_left_rear"/>
    <joint name="omni_sphere7_joint_left_rear"/>
    <mechanicalReduction>1</mechanicalReduction>
    <motorTorqueConstant>1</motorTorqueConstant>
  </transmission>
  <transmission name="omniwheel_trans_right_rear" type="pr2_mechanism_model/SimpleTransmission">
    <actuator name="omniwheel_motor_right_rear"/>
    <joint name="omni_sphere7_joint_right_rear"/>
    <mechanicalReduction>1</mechanicalReduction>
    <motorTorqueConstant>1</motorTorqueConstant>
  </transmission>
  <transmission name="omniwheel_trans_left_front" type="pr2_mechanism_model/SimpleTransmission">
    <actuator name="omniwheel_motor_left_front"/>
    <joint name="omni_sphere8_joint_left_front"/>
    <mechanicalReduction>1</mechanicalReduction>
    <motorTorqueConstant>1</motorTorqueConstant>
  </transmission>
  <transmission name="omniwheel_trans_right_front" type="pr2_mechanism_model/SimpleTransmission">
    <actuator name="omniwheel_motor_right_front"/>
    <joint name="omni_sphere8_joint_right_front"/>
    <mechanicalReduction>1</mechanicalReduction>
    <motorTorqueConstant>1</motorTorqueConstant>
  </transmission>
  <transmission name="omniwheel_trans_left_rear" type="pr2_mechanism_model/SimpleTransmission">
    <actuator name="omniwheel_motor_left_rear"/>
    <joint name="omni_sphere8_joint_left_rear"/>
    <mechanicalReduction>1</mechanicalReduction>
    <motorTorqueConstant>1</motorTorqueConstant>
  </transmission>
  <transmission name="omniwheel_trans_right_rear" type="pr2_mechanism_model/SimpleTransmission">
    <actuator name="omniwheel_motor_right_rear"/>
    <joint name="omni_sphere8_joint_right_rear"/>
    <mechanicalReduction>1</mechanicalReduction>
    <motorTorqueConstant>1</motorTorqueConstant>
  </transmission>
  <transmission name="omniwheel_trans_left_front" type="pr2_mechanism_model/SimpleTransmission">
    <actuator name="omniwheel_motor_left_front"/>
    <joint name="omni_sphere9_joint_left_front"/>
    <mechanicalReduction>1</mechanicalReduction>
    <motorTorqueConstant>1</motorTorqueConstant>
  </transmission>
  <transmission name="omniwheel_trans_right_front" type="pr2_mechanism_model/SimpleTransmission">
    <actuator name="omniwheel_motor_right_front"/>
    <joint name="omni_sphere9_joint_right_front"/>
    <mechanicalReduction>1</mechanicalReduction>
    <motorTorqueConstant>1</motorTorqueConstant>
  </transmission>
  <transmission name="omniwheel_trans_left_rear" type="pr2_mechanism_model/SimpleTransmission">
    <actuator name="omniwheel_motor_left_rear"/>
    <joint name="omni_sphere9_joint_left_rear"/>
    <mechanicalReduction>1</mechanicalReduction>
    <motorTorqueConstant>1</motorTorqueConstant>
  </transmission>
  <transmission name="omniwheel_trans_right_rear" type="pr2_mechanism_model/SimpleTransmission">
    <actuator name="omniwheel_motor_right_rear"/>
    <joint name="omni_sphere9_joint_right_rear"/>
    <mechanicalReduction>1</mechanicalReduction>
    <motorTorqueConstant>1</motorTorqueConstant>
  </transmission>
  <transmission name="omniwheel_trans_left_front" type="pr2_mechanism_model/SimpleTransmission">
    <actuator name="omniwheel_motor_left_front"/>
    <joint name="omni_sphere10_joint_left_front"/>
    <mechanicalReduction>1</mechanicalReduction>
    <motorTorqueConstant>1</motorTorqueConstant>
  </transmission>
  <transmission name="omniwheel_trans_right_front" type="pr2_mechanism_model/SimpleTransmission">
    <actuator name="omniwheel_motor_right_front"/>
    <joint name="omni_sphere10_joint_right_front"/>
    <mechanicalReduction>1</mechanicalReduction>
    <motorTorqueConstant>1</motorTorqueConstant>
  </transmission>
  <transmission name="omniwheel_trans_left_rear" type="pr2_mechanism_model/SimpleTransmission">
    <actuator name="omniwheel_motor_left_rear"/>
    <joint name="omni_sphere10_joint_left_rear"/>
    <mechanicalReduction>1</mechanicalReduction>
    <motorTorqueConstant>1</motorTorqueConstant>
  </transmission>
  <transmission name="omniwheel_trans_right_rear" type="pr2_mechanism_model/SimpleTransmission">
    <actuator name="omniwheel_motor_right_rear"/>
    <joint name="omni_sphere10_joint_right_rear"/>
    <mechanicalReduction>1</mechanicalReduction>
    <motorTorqueConstant>1</motorTorqueConstant>
  </transmission>
  <transmission name="omniwheel_trans_left_front" type="pr2_mechanism_model/SimpleTransmission">
    <actuator name="omniwheel_motor_left_front"/>
    <joint name="omni_sphere11_joint_left_front"/>
    <mechanicalReduction>1</mechanicalReduction>
    <motorTorqueConstant>1</motorTorqueConstant>
  </transmission>
  <transmission name="omniwheel_trans_right_front" type="pr2_mechanism_model/SimpleTransmission">
    <actuator name="omniwheel_motor_right_front"/>
    <joint name="omni_sphere11_joint_right_front"/>
    <mechanicalReduction>1</mechanicalReduction>
    <motorTorqueConstant>1</motorTorqueConstant>
  </transmission>
  <transmission name="omniwheel_trans_left_rear" type="pr2_mechanism_model/SimpleTransmission">
    <actuator name="omniwheel_motor_left_rear"/>
    <joint name="omni_sphere11_joint_left_rear"/>
    <mechanicalReduction>1</mechanicalReduction>
    <motorTorqueConstant>1</motorTorqueConstant>
  </transmission>
  <transmission name="omniwheel_trans_right_rear" type="pr2_mechanism_model/SimpleTransmission">
    <actuator name="omniwheel_motor_right_rear"/>
    <joint name="omni_sphere11_joint_right_rear"/>
    <mechanicalReduction>1</mechanicalReduction>
    <motorTorqueConstant>1</motorTorqueConstant>
  </transmission>
  <transmission name="omniwheel_trans_left_front" type="pr2_mechanism_model/SimpleTransmission">
    <actuator name="omniwheel_motor_left_front"/>
    <joint name="omni_sphere12_joint_left_front"/>
    <mechanicalReduction>1</mechanicalReduction>
    <motorTorqueConstant>1</motorTorqueConstant>
  </transmission>
  <transmission name="omniwheel_trans_right_front" type="pr2_mechanism_model/SimpleTransmission">
    <actuator name="omniwheel_motor_right_front"/>
    <joint name="omni_sphere12_joint_right_front"/>
    <mechanicalReduction>1</mechanicalReduction>
    <motorTorqueConstant>1</motorTorqueConstant>
  </transmission>
  <transmission name="omniwheel_trans_left_rear" type="pr2_mechanism_model/SimpleTransmission">
    <actuator name="omniwheel_motor_left_rear"/>
    <joint name="omni_sphere12_joint_left_rear"/>
    <mechanicalReduction>1</mechanicalReduction>
    <motorTorqueConstant>1</motorTorqueConstant>
  </transmission>
  <transmission name="omniwheel_trans_right_rear" type="pr2_mechanism_model/SimpleTransmission">
    <actuator name="omniwheel_motor_right_rear"/>
    <joint name="omni_sphere12_joint_right_rear"/>
    <mechanicalReduction>1</mechanicalReduction>
    <motorTorqueConstant>1</motorTorqueConstant>
  </transmission>
  <transmission name="neck_trans" type="pr2_mechanism_model/SimpleTransmission">
    <actuator name="neck_motor"/>
    <joint name="neck_pan_joint"/>
    <mechanicalReduction>1</mechanicalReduction>
    <motorTorqueConstant>1</motorTorqueConstant>
  </transmission>
  <transmission name="head_trans" type="pr2_mechanism_model/SimpleTransmission">
    <actuator name="head_motor"/>
    <joint name="neck_tilt_joint"/>
    <mechanicalReduction>1</mechanicalReduction>
    <motorTorqueConstant>1</motorTorqueConstant>
  </transmission>
  <transmission name="base_laser_trans" type="pr2_mechanism_model/SimpleTransmission">
    <actuator name="base_laser_motor"/>
    <joint name="base_laser_joint"/>
    <mechanicalReduction>1</mechanicalReduction>
    <motorTorqueConstant>1</motorTorqueConstant>
  </transmission>
  <transmission name="top_laser_trans" type="pr2_mechanism_model/SimpleTransmission">
    <actuator name="top_laser_motor"/>
    <joint name="top_laser_joint"/>
    <mechanicalReduction>1</mechanicalReduction>
    <motorTorqueConstant>1</motorTorqueConstant>
  </transmission>
</robot>

