<?xml version="1.0"?>
<robot xmlns:xacro="http://ros.org/wiki/xacro">


<!--body-->
<xacro:my_link_texturedmesh_diff_coll name="base" mass="20" texture="bottomcovers">
   <origin xyz="0.0 0.0 0.3275" rpy="0 0 0"/>
   <origin xyz="0.0 0.0 0.23" rpy="0 0 -1.5708" />
   <origin xyz="0.0 0.0 0.33" rpy="0 0 -1.5708" />
   <inertia ixx="2.63"  ixy="0"  ixz="0" iyy="2.63" iyz="0" izz="2.4" /> <!--*-->
   <mesh filename="package://amigo_robot_model/body/bottomcovers.dae" scale="0.001 0.001 0.001"/>
   <box size="0.275 0.275 0.6"/>
</xacro:my_link_texturedmesh_diff_coll>

<xacro:my_link_texturedmesh name="torso_slider" mass="0.1" texture="aluminum">
   <origin xyz="0 0 0" rpy="0 0 0"/>
   <origin xyz="-0.35 0.0 0.0" rpy="0 1.5708 0"/>
   <inertia ixx="0.01"  ixy="0"  ixz="0" iyy="0.01" iyz="0" izz="0.01" />
   <mesh filename="package://amigo_robot_model/body/torsoslidertextured.dae" scale="0.01 0.01 0.01"/>
</xacro:my_link_texturedmesh>

<xacro:my_link name="base_link" mass="0" color="Red">
   <cylinder radius="0.0" length="0.00" />
   <origin xyz="0.0 0.0 0.0" rpy="0 0 0"/>
   <origin xyz="0.0 0.0 0.0" rpy="0 0 0" />
   <inertia ixx="0"  ixy="0"  ixz="0" iyy="0" iyz="0" izz="0" /> 
</xacro:my_link>

<link name="batterycovercollision_left">
   <inertial>
     <origin xyz="0.0 0.0 0.0" />
     <mass value="0.001"/>
     <inertia ixx="0.01"  ixy="0"  ixz="0" iyy="0.01" iyz="0" izz="0.01" />
   </inertial>
    <visual>
		<origin xyz="0.0 0.0 0.0" />
		<geometry>
			<box size="0.0 0.0 0.0"/>
		</geometry>
    </visual>
    <collision>
		<origin xyz="0.0 0.0 0.0" />
		<geometry>
			<box size="0.25 0.15 0.125"/>
		</geometry>
    </collision>
</link>

<joint name="batterycovercollision_left_joint" type="fixed">
    <parent link="base"/>
    <child link="batterycovercollision_left"/>
    <axis xyz="1 0 0"/>
    <origin xyz="0.0 0.25 0.1" rpy="0 0 0"/>
</joint>

<link name="batterycovercollision_right">
   <inertial>
     <origin xyz="0.0 0.0 0.0" />
     <mass value="0.001"/>
     <inertia ixx="0.01"  ixy="0"  ixz="0" iyy="0.01" iyz="0" izz="0.01" />
   </inertial>
    <visual>
		<origin xyz="0.0 0.0 0.0" />
		<geometry>
			<box size="0.0 0.0 0.0"/>
		</geometry>
    </visual>
    <collision>
		<origin xyz="0.0 0.0 0.0" />
		<geometry>
			<box size="0.25 0.15 0.125"/>
		</geometry>
    </collision>
</link>

<joint name="batterycovercollision_right_joint" type="fixed">
    <parent link="base"/>
    <child link="batterycovercollision_right"/>
    <axis xyz="1 0 0"/>
    <origin xyz="0.0 -0.25 0.1" rpy="0 0 0"/>
</joint>

<link name="batterycovercollision_back">
   <inertial>
     <origin xyz="0.0 0.0 0.0" />
     <mass value="0.001"/>
     <inertia ixx="0.01"  ixy="0"  ixz="0" iyy="0.01" iyz="0" izz="0.01" />
   </inertial>
    <visual>
		<origin xyz="0.0 0.0 0.0" />
		<geometry>
			<box size="0.0 0.0 0.0"/>
		</geometry>
    </visual>
    <collision>
		<origin xyz="0.0 0.0 0.0" />
		<geometry>
			<box size="0.25 0.15 0.175"/>
		</geometry>
    </collision>
</link>

<joint name="batterycovercollision_back_joint" type="fixed">
    <parent link="base"/>
    <child link="batterycovercollision_back"/>
    <axis xyz="1 0 0"/>
    <origin xyz="-0.25 0.0 0.125" rpy="0 0 1.5708"/>
</joint>


<xacro:my_link_texturedmesh name="torso" mass="16" texture="white">
   <origin xyz="0.0 0.0 0.0" rpy="0 0 0"/>
   <origin xyz="0.045 0.0 0.06" rpy="-1.5708 0 -1.5708" />
   <inertia ixx="0.01"  ixy="0"  ixz="0" iyy="0.01" iyz="0" izz="0.01" /> <!--*-->
   <mesh filename="package://amigo_robot_model/body/torsocovers.dae" scale="0.001 0.001 0.001"/>
</xacro:my_link_texturedmesh>

  <joint name="spindle_joint" type="prismatic">
    <parent link="base"/>
    <child link="torso_slider"/>
    <axis xyz="1 0 0"/>
    <origin xyz="0.0 0.0 0.58" rpy="3.14159265 -1.5708 0"/>
    <dynamics damping="3" friction="0.0"/> <!--*-->
    <limit effort="30" velocity="1.0" lower="0.0" upper="0.41" /> <!--*-->
  </joint>

  <joint name="base_link_joint" type="fixed">
    <parent link="base_link"/>
    <child link="base"/>
    <axis xyz="1 0 0"/>
    <origin xyz="0.0 0.0 0.055" rpy="0 0 0"/>
  </joint>
  
    <joint name="torso_slider_joint" type="fixed">
    <parent link="torso_slider"/>
    <child link="torso"/>
    <axis xyz="1 0 0"/>
    <origin xyz="0.135 0.0 0.0" rpy="0 0 0"/>
  </joint>

</robot>
